Workbook

Sheet CWI Summary
A1: Summary For ICICI Bank, Chaphekar Chowk, Pune
A3: Address | B3: ICICI Bank LTD, Chaphekar Chowk, chinchwad, Pune
A4: Contractor | B4: Bella Inter Décor
A5: Area | B5: 1266 Sqft
A6: SOL ID | B6: 5871
A7: FINAL SUMMARY
A9: Sr.No. | B9: Item | C9: Amount of work order | D9: Amount of CWI | E9: Excess | F9: Saving | G9: Total
A10: I | B10: CIVIL WORKS | C10: =SUMIF(BOQ!$B$4:$B$113,'CWI Summary'!$B10,BOQ!$J$4:$J$113) | D10: =SUMIF(BOQ!$B$4:$B$113,'CWI Summary'!$B10,BOQ!$N$4:$N$113) | E10: =SUMIF(BOQ!$B$4:$B$113,'CWI Summary'!$B10,BOQ!$R$4:$R$113) | F10: =SUMIF(BOQ!$B$4:$B$113,'CWI Summary'!$B10,BOQ!$S$4:$S$113) | G10: =SUMIF(BOQ!$B$4:$B$113,'CWI Summary'!$B10,BOQ!$T$4:$T$113)
A11: II | B11: Carpentry Work | C11: =SUMIF(BOQ!$B$4:$B$113,'CWI Summary'!$B11,BOQ!$J$4:$J$113) | D11: =SUMIF(BOQ!$B$4:$B$113,'CWI Summary'!$B11,BOQ!$N$4:$N$113) | E11: =SUMIF(BOQ!$B$4:$B$113,'CWI Summary'!$B11,BOQ!$R$4:$R$113) | F11: =SUMIF(BOQ!$B$4:$B$113,'CWI Summary'!$B11,BOQ!$S$4:$S$113) | G11: =SUMIF(BOQ!$B$4:$B$113,'CWI Summary'!$B11,BOQ!$T$4:$T$113)
A12: III | B12: Electrical Works | C12: =SUMIF(BOQ!$B$4:$B$113,'CWI Summary'!$B12,BOQ!$J$4:$J$113) | D12: =SUMIF(BOQ!$B$4:$B$113,'CWI Summary'!$B12,BOQ!$N$4:$N$113) | E12: =SUMIF(BOQ!$B$4:$B$113,'CWI Summary'!$B12,BOQ!$R$4:$R$113) | F12: =SUMIF(BOQ!$B$4:$B$113,'CWI Summary'!$B12,BOQ!$S$4:$S$113) | G12: =SUMIF(BOQ!$B$4:$B$113,'CWI Summary'!$B12,BOQ!$T$4:$T$113)
A13: IV | B13: Non-Interior Works | C13: =SUMIF(BOQ!$B$4:$B$113,'CWI Summary'!$B13,BOQ!$J$4:$J$113) | D13: =SUMIF(BOQ!$B$4:$B$113,'CWI Summary'!$B13,BOQ!$N$4:$N$113) | E13: =SUMIF(BOQ!$B$4:$B$113,'CWI Summary'!$B13,BOQ!$R$4:$R$113) | F13: =SUMIF(BOQ!$B$4:$B$113,'CWI Summary'!$B13,BOQ!$S$4:$S$113) | G13: =SUMIF(BOQ!$B$4:$B$113,'CWI Summary'!$B13,BOQ!$T$4:$T$113)
A14: V | B14: Electricity &Diesel Expenses to TKO | C14: =SUMIF(BOQ!$B$4:$B$113,'CWI Summary'!$B14,BOQ!$J$4:$J$113) | D14: =SUMIF(BOQ!$B$4:$B$113,'CWI Summary'!$B14,BOQ!$N$4:$N$113) | E14: =SUMIF(BOQ!$B$4:$B$113,'CWI Summary'!$B14,BOQ!$R$4:$R$113) | F14: =SUMIF(BOQ!$B$4:$B$113,'CWI Summary'!$B14,BOQ!$S$4:$S$113) | G14: =SUMIF(BOQ!$B$4:$B$113,'CWI Summary'!$B14,BOQ!$T$4:$T$113)
A15: VI | B15: Reimbursement of Vendor Elements | C15: =SUMIF(BOQ!$B$4:$B$113,'CWI Summary'!$B15,BOQ!$J$4:$J$113) | D15: =SUMIF(BOQ!$B$4:$B$113,'CWI Summary'!$B15,BOQ!$N$4:$N$113) | E15: =SUMIF(BOQ!$B$4:$B$113,'CWI Summary'!$B15,BOQ!$R$4:$R$113) | F15: =SUMIF(BOQ!$B$4:$B$113,'CWI Summary'!$B15,BOQ!$S$4:$S$113) | G15: =SUMIF(BOQ!$B$4:$B$113,'CWI Summary'!$B15,BOQ!$T$4:$T$113)
A16: VII
A17: VIII
A18: A | B18: TOTAL | C18: =SUM(C10:C17) | D18: =SUM(D10:D17) | E18: =SUM(E10:E17) | F18: =SUM(F10:F17) | G18: =SUM(G10:G17)
A19: TAXES
B20: Taxes as applicable (pl indicate applicable taxes)
A21: a)
A22: b) | C22: =C18*9% | D22: =D18*9% | E22: =E18*9% | F22: =F18*9% | G22: =G18*9%
A23: c) | C23: =C18*9% | D23: =D18*9% | E23: =E18*9% | F23: =F18*9% | G23: =G18*9%
A25: B | B25: Total | C25: =SUM(C20:C24) | D25: =SUM(D20:D24) | E25: =SUM(E20:E24) | F25: =SUM(F20:F24) | G25: =SUM(G20:G24)
A27: (A + B) | B27: Grand Total (incl. taxes) | C27: =C18+C25 | D27: =D18+D25 | E27: =E18+E25 | F27: =F18+F25 | G27: =G18+G25

Sheet Extracted Data
A1: Sr.No | B1: Particulars | C1: As per CWI (Qty)
A2: 0 | B2: Reimbursement of Diesel for DG | C2: 1
A3: 0 | B3: Providing and fixing soft board incl of 6mm ply base backing and 12mm thk. crock sheet which is wrapped all around with fabric [Burgandy for regular office areas and royal blue for Private banking].The edge trims to be finished in 19mmx 6mm lipping p | C3: 50
A4: 0 | B4: Rubber Mat in UPS room, 20mm thickness. | C4: 29
A5: 0 | B5: Provision and installation of master switch nearest to the entrance of the premises, as per the specifications. | C5: 1
A6: 0 | B6: ATM wall design in Grey and white with 40mm commercial ply and laminate in high gloss finish and Rehau make edge banding as per approve design. Rs.7000 for one ATM and Rs.5000 for every additional machines. Quantity not to exceed 1 no. per site. | C6: 1
A7: 0 | B7: ATM wall design in Grey and white with 40mm commercial ply and laminate in high gloss finish and Rehau make edge banding as per approve design, for every additional machines | C7: 1
A8: 0 | B8: Providing and fixing wall mounted metal FAN 18 inch make orient, havells and almourd.orient, havells and almounard | C8: 2
A9: 0 | B9: 8 feet aluminium foladable Ladder As per sample approved . As per approved make | C9: 1
A10: 0 | B10: Providing and fixing of Clay Flower pot 12 to 20 for branch lobby area with neceessary accessories, including IGBC approved indoor plant. | C10: 5
A11: 0 | B11: Providing and fixing Lacqured glass in Fusion Orange colour for Theme wall. Make - Saint Gobain, Asahi | C11: 84
A12: 0 | B12: Plant as per IGBC list, 2 feet height of plant, 10 inch height plastic pot with plastic tray | C12: 13
A13: 0 | B13: Electrical work inclusive of power points, light points, A.C. cabling and distribution boards, fire detection and provision of conduits for networking, LED, raceway. BEE rated items for green certification | C13: 1266
... A111: 0 | B111: Aluminium Door Frame 50mmx 38mm ( Door Size - 1050 x 2400mm ) | C111: 2

Sheet BOQ
A1: FINAL BILL FOR ICICI BANK LTD, CHAPHEKAR CHOWK_PUNE
H2: As per WO | K2: As per CWI | P2: Variance : CWI vs WO | R2: Excess | S2: Saving | T2: Total | U2: CWI Remark | V2: Remark | W2: PM Approval
A3: TYPE | B3: NATURE OF WORK | C3: CATEGORY | D3: SUB CATEGORY | E3: Particulars | F3: Brand/ Make used/ installed at site | G3: UNIT | H3: RATE | I3: QTY | J3: AMOUNT | K3: RATE | L3: QTY | M3: Photographic QTY | N3: AMOUNT | O3: Vendor RE | P3: QTY | Q3: AMOUNT
A4: Reimbursable Items | B4: Electricity &Diesel Expenses to TKO | C4: Electricity &Diesel Expenses to TKO | D4: Diesel for DG | E4: Reimbursement of Diesel for DG | F4: NA | G4: L.sum | H4: 3000 | I4: 1 | J4: 3000 | K4: =3000*1.2 | L4: ='Measurement Sheet'!J8 | N4: =K4*L4 | O4: Bill Attatached | P4: =L4-I4 | Q4: =N4-J4 | R4: =IF(N4>J4,(N4-J4),0) | S4: =IF(N4<J4,(N4-J4),0) | T4: =S4+R4 | V4: Quantity Exceeded from the Work order project Manager Approval Required
A5: Main BOQ | B5: Carpentry Work | C5: MISCELLANEOUS | D5: Softboard in Managers cabin-cubicle , 5S and Customer area Notice Board | E5: Providing and fixing soft board incl of 6mm ply base backing and 12mm thk. crock sheet which is wrapped all around with fabric [Burgandy for regular office areas and royal blue for Private banking].The edge trims to be finished in 19mmx 6mm lipping p | F5: Samrat | G5: Sft | H5: 150 | I5: 60 | J5: 9000 | K5: 150 | L5: ='Measurement Sheet'!J17 | N5: =K5*L5 | P5: =L5-I5 | Q5: =N5-J5 | R5: =IF(N5>J5,(N5-J5),0) | S5: =IF(N5<J5,(N5-J5),0) | T5: =S5+R5
A6: Main BOQ | B6: Carpentry Work | C6: MISCELLANEOUS | D6: Rubber Mat in UPS room | E6: Rubber Mat in UPS room, 20mm thickness. | F6: NA | G6: Sft | H6: 140 | I6: 27 | J6: 3780 | K6: 140 | L6: ='Measurement Sheet'!J23 | N6: =K6*L6 | P6: =L6-I6 | Q6: =N6-J6 | R6: =IF(N6>J6,(N6-J6),0) | S6: =IF(N6<J6,(N6-J6),0) | T6: =S6+R6 | V6: Quantity Exceeded from the Work order project Manager Approval Required
A7: Main BOQ | B7: Electrical Works | C7: Other Electricals | D7: Master Switch | E7: Provision and installation of master switch nearest to the entrance of the premises, as per the specifications. | F7: L&T | G7: Nos | H7: 30000 | I7: 1 | J7: 30000 | K7: 30000 | L7: ='Measurement Sheet'!J29 | N7: =K7*L7 | P7: =L7-I7 | Q7: =N7-J7 | R7: =IF(N7>J7,(N7-J7),0) | S7: =IF(N7<J7,(N7-J7),0) | T7: =S7+R7
A8: Main BOQ | B8: Carpentry Work | C8: PARTITIONS AND PANELLING | D8: ATM backdrop | E8: ATM wall design in Grey and white with 40mm commercial ply and laminate in high gloss finish and Rehau make edge banding as per approve design. Rs.7000 for one ATM and Rs.5000 for every additional machines. Quantity not to exceed 1 no. per site. | F8: Samrat | G8: Nos | H8: 7000 | I8: 1 | J8: 7000 | K8: 7000 | L8: ='Measurement Sheet'!J35 | N8: =K8*L8 | P8: =L8-I8 | Q8: =N8-J8 | R8: =IF(N8>J8,(N8-J8),0) | S8: =IF(N8<J8,(N8-J8),0) | T8: =S8+R8
A9: Main BOQ | B9: Carpentry Work | C9: PARTITIONS AND PANELLING | D9: ATM Backdrop for additional machines | E9: ATM wall design in Grey and white with 40mm commercial ply and laminate in high gloss finish and Rehau make edge banding as per approve design, for every additional machines | F9: Samrat | G9: Nos | H9: 5000 | I9: 1 | J9: 5000 | K9: 5000 | L9: ='Measurement Sheet'!J41 | N9: =K9*L9 | P9: =L9-I9 | Q9: =N9-J9 | R9: =IF(N9>J9,(N9-J9),0) | S9: =IF(N9<J9,(N9-J9),0) | T9: =S9+R9
A10: Main BOQ | B10: Electrical Works | C10: Other Electricals | D10: Wall Mounted Fan | E10: Providing and fixing wall mounted metal FAN 18 inch make orient, havells and almourd.orient, havells and almounard | F10: Almourd | G10: nos | H10: 4500 | I10: 2 | J10: 9000 | K10: 4500 | L10: ='Measurement Sheet'!J49 | N10: =K10*L10 | P10: =L10-I10 | Q10: =N10-J10 | R10: =IF(N10>J10,(N10-J10),0) | S10: =IF(N10<J10,(N10-J10),0) | T10: =S10+R10
A11: Main BOQ | B11: Carpentry Work | C11: MISCELLANEOUS | D11: Aluminium Foldable Ladder | E11: 8 feet aluminium foladable Ladder As per sample approved . As per approved make | F11: NA | G11: nos | H11: 7500 | I11: 1 | J11: 7500 | K11: 7500 | L11: ='Measurement Sheet'!J55 | N11: =K11*L11 | P11: =L11-I11 | Q11: =N11-J11 | R11: =IF(N11>J11,(N11-J11),0) | S11: =IF(N11<J11,(N11-J11),0) | T11: =S11+R11
A12: Main BOQ | B12: Carpentry Work | C12: MISCELLANEOUS | D12: FLOWER POT | E12: Providing and fixing of Clay Flower pot 12 to 20 for branch lobby area with neceessary accessories, including IGBC approved indoor plant. | F12: NA | G12: No | H12: 1000 | I12: 5 | J12: 5000 | K12: 1000 | L12: ='Measurement Sheet'!J61 | N12: =K12*L12 | P12: =L12-I12 | Q12: =N12-J12 | R12: =IF(N12>J12,(N12-J12),0) | S12: =IF(N12<J12,(N12-J12),0) | T12: =S12+R12
A13: Main BOQ | B13: Carpentry Work | C13: MISCELLANEOUS | D13: Lacqured Glass new | E13: Providing and fixing Lacqured glass in Fusion Orange colour for Theme wall. Make - Saint Gobain, Asahi | F13: Saint Gobain (10mm Thick Glass) | G13: sqft | H13: 525 | I13: 56 | J13: 29400 | K13: 525 | L13: ='Measurement Sheet'!J69 | N13: =K13*L13 | P13: =L13-I13 | Q13: =N13-J13 | R13: =IF(N13>J13,(N13-J13),0) | S13: =IF(N13<J13,(N13-J13),0) | T13: =S13+R13 | V13: Quantity Exceeded from the Work order project Manager Approval Required
A14: Main BOQ | B14: Carpentry Work | C14: MISCELLANEOUS | D14: IGBC planters | E14: Plant as per IGBC list, 2 feet height of plant, 10 inch height plastic pot with plastic tray | F14: NA | G14: Each | H14: 500 | I14: 13 | J14: 6500 | K14: 500 | L14: ='Measurement Sheet'!J75 | N14: =K14*L14 | P14: =L14-I14 | Q14: =N14-J14 | R14: =IF(N14>J14,(N14-J14),0) | S14: =IF(N14<J14,(N14-J14),0) | T14: =S14+R14
A15: Main BOQ | B15: Electrical Works | C15: Other Electricals | D15: Electricals as per Electrical Annexure 1 attached with this BOQ | E15: Electrical work inclusive of power points, light points, A.C. cabling and distribution boards, fire detection and provision of conduits for networking, LED, raceway. BEE rated items for green certification | F15: NA | G15: Sft | H15: 310 | I15: 1266 | J15: 392460 | K15: 310 | L15: ='Measurement Sheet'!J81 | N15: =K15*L15 | P15: =L15-I15 | Q15: =N15-J15 | R15: =IF(N15>J15,(N15-J15),0) | S15: =IF(N15<J15,(N15-J15),0) | T15: =S15+R15
A16: Main BOQ | B16: CIVIL WORKS | C16: PLUMBING WORKS AND SANITARY FITTINGS | D16: Internal CPVC Plumbing work. [ Toilets and Pantry ] | E16: Providing and fixing 0.5 or 0.75 inch or 1 inch CPVC pipes of Supreme or Astral or Ashirwad or Prince make for distribution in toilets and pantry including ftchase cutting, chase filing, coat of primer, antirust paint at all joints, proper insulation in Jute cloth and Black japan treatment comp, Internal concealed plumbing works for water supply, drainage and related works per toilet comprising of wash basin, WC, angle valve etc. all complete. Ladies Toilet [1 Wash Basin with 1 EWC] as directed by engineering incharge | F16: Prince | G16: Lsum | H16: 5000 | I16: 3 | J16: 15000 | K16: 5000 | L16: ='Measurement Sheet'!J91 | N16: =K16*L16 | P16: =L16-I16 | Q16: =N16-J16 | R16: =IF(N16>J16,(N16-J16),0) | S16: =IF(N16<J16,(N16-J16),0) | T16: =S16+R16
A17: Main BOQ | B17: CIVIL WORKS | C17: FLOORING AND DADO | D17: Water-proofing of toilet sunk and Pantry | E17: WATER PROOFING IN TOILETS FLOOR &WALLS UPTO 2ft Ht : PROVIDING OF WATER PROOFING - CHEMICAL TREATMENT - THE SLAB TO BE CLEANED AND APPLY 2 COATS OF 2MM CHEMICAL ON THE FLOOR AND ON THE PERIPHERAL WALLS [UPTO 1 METRE HEIGHT] BASE COAT - APPLYING BASE COAT OF 1:6 MORTAR OVER CHEMICAL TREATMENT ON THE FLOOR AND ON THE PERIPHERAL WALLS UPTO 1000MM. Make - Dr. Fix-it, Pidilite, Sunandha | F17: Dr Fixit | G17: Sft | H17: 65 | I17: 259 | J17: 16835 | K17: 65 | L17: ='Measurement Sheet'!J123 | N17: =K17*L17 | P17: =L17-I17 | Q17: =N17-J17 | R17: =IF(N17>J17,(N17-J17),0) | S17: =IF(N17<J17,(N17-J17),0) | T17: =S17+R17
A18: Main BOQ | B18: CIVIL WORKS | C18: FLOORING AND DADO | D18: Brick Bat Coba in Toilet Area | E18: Providing and laying of raised floor upto 200mm ht with necessary Brick bat coba - Waste water lines to be encased with 1:3:6 grade concrete and applying brick bat coba [1:6 mortar], The mortar for the brick- bat coba filling shall be CM 1:4 and admixed with integral waterproofing compound, curing, complete. curing 2 days and then finishing the surface with 10 mm thk of 1:6 mortar to proper level and slope. Rate to include necessary steps and ramp as per architects and clients instructions. | F18: NA | G18: Sft | H18: 75 | I18: 77 | J18: 5775 | K18: 75 | L18: ='Measurement Sheet'!J138 | N18: =K18*L18 | P18: =L18-I18 | Q18: =N18-J18 | R18: =IF(N18>J18,(N18-J18),0) | S18: =IF(N18<J18,(N18-J18),0) | T18: =S18+R18 | V18: Quantity Exceeded from the Work order project Manager Approval Required
A19: Main BOQ | B19: Carpentry Work | C19: DOORS AND WINDOWS | D19: Door frame in Ply | E19: Providing and fixing door frames made out of 18mm double Ply finished with laminate of approved shade. frame section of size Approx upto 150mm x 36mm including providing necessary anchor hold fasts, cutouts as per engineer - in charge. | F19: Samrat | G19: rft | H19: 160 | I19: 100 | J19: 16000 | K19: 160 | L19: ='Measurement Sheet'!J144 | N19: =K19*L19 | P19: =L19-I19 | Q19: =N19-J19 | R19: =IF(N19>J19,(N19-J19),0) | S19: =IF(N19<J19,(N19-J19),0) | T19: =S19+R19
A20: Main BOQ | B20: Carpentry Work | C20: DOORS AND WINDOWS | D20: Fixed Glazing | E20: Providing and fixing full height partition using 12mm thick toughened glass with top &bottom C Channel etc. complete. The glass edges shall be polish on all sides. The entire fixed partition shall be errected in complete line &level. as per instruction of Architect or Bank including other arrangement for necessary support. Make - Saint Gobain glass or Asahi or Modiguard | F20: Saint Gobain (10mm Thick Glass) | G20: sft | H20: 450 | I20: 469 | J20: 211050 | K20: 450 | L20: ='Measurement Sheet'!J165 | N20: =K20*L20 | P20: =L20-I20 | Q20: =N20-J20 | R20: =IF(N20>J20,(N20-J20),0) | S20: =IF(N20<J20,(N20-J20),0) | T20: =S20+R20 | V20: Quantity Exceeded from the Work order project Manager Approval Required
A21: Main BOQ | B21: Carpentry Work | C21: DOORS AND WINDOWS | D21: Cabin and Other doors _Fully Glazed | E21: Providing and fixing Single Shutter, 12mm thick toughened glass of size 900 x 2100mm and approved make as shutters on patch fittings of specified make, floor spring, 600mm Handle, Inculding all other accessories, hardware etc. complete.Glass Make - Saint Gobain glass orAsahi or Modiguard, Hardware : Dorma BTS 58 | F21: Saint Gobain (10mm Thick Glass) | G21: nos | H21: 23500 | I21: 3 | J21: 70500 | K21: 23500 | L21: ='Measurement Sheet'!J175 | N21: =K21*L21 | P21: =L21-I21 | Q21: =N21-J21 | R21: =IF(N21>J21,(N21-J21),0) | S21: =IF(N21<J21,(N21-J21),0) | T21: =S21+R21
A22: Main BOQ | B22: Carpentry Work | C22: DOORS AND WINDOWS | D22: Main Entrance doors for Branch and ATM | E22: Providing and fixing Single Shutter, 12mm thick toughened glass of size 1050 x 2100mm and approved make as shutters on patch fittings of specified make, floor spring, Handle of 12 inch long x 4inch bended width with 1inch outer Diameter, Inculding all other accssories, hard ware etc. complete [Floor Mounted Floor Spring from Dorma BTS75], Make - Saint Gobain glass or Asahi or Modiguard with Dorma Accessories | F22: Saint Gobain (10mm Thick Glass) | G22: nos | H22: 28500 | I22: 1 | J22: 28500 | K22: 28500 | L22: ='Measurement Sheet'!J183 | N22: =K22*L22 | P22: =L22-I22 | Q22: =N22-J22 | R22: =IF(N22>J22,(N22-J22),0) | S22: =IF(N22<J22,(N22-J22),0) | T22: =S22+R22 | V22: Quantity Exceeded from the Work order project Manager Approval Required
A23: Non-Interior Work | B23: Non-Interior Works | C23: DISMANTLING AND DEMOLITION | D23: Pest-Control and Anti Termite Treatment | E23: Providing Pest control and Anti-termite treatment by a specialized agency as per the specifications mentioned by the Bureau of Indian Standards and Agencies specifications [whichever is higher], for General Civil, Plumbing, Drainage and timber Carpentry works, including a 10-year guarantee under suitable undertaking on stamp paper etc, complete as directed. [ Mode of measurement shall be on the carpet-area of the floor and not the area of surfaces treated.] Contractor is suppose to submit the Certificate of Completion of the same. | F23: Hytech | G23: Sqf | H23: 10 | I23: 1151 | J23: 11510 | K23: 10 | L23: ='Measurement Sheet'!J189 | N23: =K23*L23 | P23: =L23-I23 | Q23: =N23-J23 | R23: =IF(N23>J23,(N23-J23),0) | S23: =IF(N23<J23,(N23-J23),0) | T23: =S23+R23
A24: Non-Interior Work | B24: Non-Interior Works | C24: DISMANTLING AND DEMOLITION | D24: Existing wall | E24: Dismantling of any existing 6inch &9inch walls with removal of lintels , chajjas, slabs if any , etc with necessary tools and tackels and carrying the debris away from site as per engineer- incharge instruction. | F24: NA | G24: Sft | H24: 10 | I24: 601 | J24: 6010 | K24: 10 | L24: ='Measurement Sheet'!J195 | N24: =K24*L24 | P24: =L24-I24 | Q24: =N24-J24 | R24: =IF(N24>J24,(N24-J24),0) | S24: =IF(N24<J24,(N24-J24),0) | T24: =S24+R24
A25: Non-Interior Work | B25: Non-Interior Works | C25: DISMANTLING AND DEMOLITION | D25: Debris Disposal | E25: Debris to be collected from the floor level &stored in allotted debris yard in proper &durable gunny bags, debris not to be left or dumped anywhere in the site areas other than the allotted debris yard. Contractor to cart off the debris through tractors or any other logistic arrangement from the debris yard to the debris disposal area outside the premises at his own risk on a daily basis or weekly basis as per the guidelines provided by engineer-in charge. | F25: NA | G25: Truck | H25: 4000 | I25: 12 | J25: 48000 | K25: 4000 | L25: ='Measurement Sheet'!J201 | N25: =K25*L25 | P25: =L25-I25 | Q25: =N25-J25 | R25: =IF(N25>J25,(N25-J25),0) | S25: =IF(N25<J25,(N25-J25),0) | T25: =S25+R25
A26: Main BOQ | B26: Carpentry Work | C26: DOORS AND WINDOWS | D26: Low Height Door for Teller | E26: Providing &fixing door as per design &size and including Godrej tribolt latch lock. Size of door to match the height of side partition. [approx 5ft x 2ft-6 ] | F26: Samrat | G26: nos | H26: 5500 | I26: 1 | J26: 5500 | K26: 5500 | L26: ='Measurement Sheet'!J209 | N26: =K26*L26 | P26: =L26-I26 | Q26: =N26-J26 | R26: =IF(N26>J26,(N26-J26),0) | S26: =IF(N26<J26,(N26-J26),0) | T26: =S26+R26 | V26: Quantity Exceeded from the Work order project Manager Approval Required
A27: Main BOQ | B27: CIVIL WORKS | C27: FLOORING AND DADO | D27: Vitrified Tile for Flooring | E27: Providing and fixing of vitrified tiles of minimum 600x600mm size confirming to IS 15622 of approved make in all colors and shades approved by Engineer-in-charge including 12-15mm thick base coat of cement mortar 1:4 [ using coarse river sand ] and jointing with grey cement slurry @ 3.3 kg per sq.m including pointing with white cement based tile grout of approved make of matching shade complete as per patterns, drawings and specifications all as directed by Engineer-in-charge. Basic Rate - Rs 60 per Sft. Make- RAK,Johnson,Kajaria | F27: RAK | G27: Sft | H27: 130 | I27: 127 | J27: 16510 | K27: 130 | L27: ='Measurement Sheet'!J223 | N27: =K27*L27 | P27: =L27-I27 | Q27: =N27-J27 | R27: =IF(N27>J27,(N27-J27),0) | S27: =IF(N27<J27,(N27-J27),0) | T27: =S27+R27 | V27: Quantity Exceeded from the Work order project Manager Approval Required
A28: Main BOQ | B28: CIVIL WORKS | C28: FLOORING AND DADO | D28: Vitrified Tile for Flooring 80x80 | E28: Providing and fixing of vitrified tiles of minimum 800x800mm size confirming to IS 15622 of approved make in all colors and shades approved by Engineer-in-charge including 12-15mm thick base coat of cement mortar 1:4 [ using coarse river sand ] and jointing with grey cement slurry @ 3.3 kg per sq.m including pointing with white cement based tile grout of approved make of matching shade complete as per patterns, drawings and specifications all as directed by Engineer-in-charge. Basic Rate - Rs 75per Sft. Make - Johnson,RAK,Kajaria | F28: RAK | G28: Sft | H28: 145 | I28: 861 | J28: 124845 | K28: 145 | L28: ='Measurement Sheet'!J245 | N28: =K28*L28 | P28: =L28-I28 | Q28: =N28-J28 | R28: =IF(N28>J28,(N28-J28),0) | S28: =IF(N28<J28,(N28-J28),0) | T28: =S28+R28 | V28: Quantity Exceeded from the Work order project Manager Approval Required
A29: Main BOQ | B29: Carpentry Work | C29: LOOSE FURNITURE | D29: Cash counter - ALLEN TYPE | E29: Providing and fixing modular Cash Counter as per detail incl. of postformed table tops of ply or E1 grade MDF, pedestal units, both sides partitions, 12mm thk clear glass on both sides,key board, etc.complete. All finished in laminate of approved shade. Cost to include SS Hardware, tribolt lock, D brackets components and all necessary provisions of boxing for conduiting and termination of electrical and data points. [4ft-0 x 6ft-9 ] With pedestal unit as per design 2ft-2 height with 3 drawers. All hinges and side telescopic channels to be considered are of compacted and of EBCO, Al-Bihari make. All the drawers to have single channel locks. All necessary accessories needs to be considered. BIFMA, Green Pro or Green guard certified. Ply or MDF E1 grade, make- Century, Green ply, Samrat. Laminate - Merino, Century, Greenlam, Aica sunmica, Base rate of laminate:Rs.50 per sft. MDF Make - Merino, Century, Greenpanel | F29: Samrat | G29: Nos | H29: 35000 | I29: 1 | J29: 35000 | K29: 35000 | L29: ='Measurement Sheet'!J251 | N29: =K29*L29 | P29: =L29-I29 | Q29: =N29-J29 | R29: =IF(N29>J29,(N29-J29),0) | S29: =IF(N29<J29,(N29-J29),0) | T29: =S29+R29
A30: Main BOQ | B30: Carpentry Work | C30: DOORS AND WINDOWS | D30: Doors into Service areas _Solid with view panelorSlit | E30: Providing and fixing Single Shutter door of size 3ft x 7ft and made up of 32 mm blockboard finished in on both sides with the laminate as per the approved sample. incl of brushed steel handle [22 mm dia pipe -ht 200mm] of approved make and 10mm thk clear float glass vision panel of 4 inch x 60 inch size and with door-closers as per details including all necessary accessories. Ply make- conforming to IS: 303 [Century,Greenply,Samrat] Make - Saint Gobain glass or Asahi or Modiguard Laminate - Merino, Century, Greenlam, Samrat.Base rate of laminate:Rs.50 per sft, Hardware : Dorma, Ozone, Hafele | F30: Samrat | G30: nos | H30: 11500 | I30: 5 | J30: 57500 | K30: 11500 | L30: ='Measurement Sheet'!J259 | N30: =K30*L30 | P30: =L30-I30 | Q30: =N30-J30 | R30: =IF(N30>J30,(N30-J30),0) | S30: =IF(N30<J30,(N30-J30),0) | T30: =S30+R30
A31: Main BOQ | B31: Carpentry Work | C31: LOOSE FURNITURE | D31: Service Counter ALLEN TYPE with pedastal units | E31: Providing and fixing modular service counter table as per detail with top of 0.75 inch ply or E1 grade MDF finished on upper surface in Postformed Laminate of approved shade &on lower surface in balancing laminate incl. of key board &pedestal unit with 3 in 1 godrej make lock as per design 2ft-2 height, metallic keyboard tray[EBCO make] All necessary accessories needs to be considered. Ply make- Century, Green ply, Samrat. Laminate - Merino, Century, Greenlam, Aica sunmica, Base rate of laminate:Rs.50 per sft. MDF Make - Merino, Century, Greenpanel. | F31: Samrat | G31: Nos | H31: 19000 | I31: 5 | J31: 95000 | K31: 19000 | L31: ='Measurement Sheet'!J265 | N31: =K31*L31 | P31: =L31-I31 | Q31: =N31-J31 | R31: =IF(N31>J31,(N31-J31),0) | S31: =IF(N31<J31,(N31-J31),0) | T31: =S31+R31
A32: Main BOQ | B32: CIVIL WORKS | C32: FLOORING AND DADO | D32: Vitrified Tile Skirting | E32: Providing and fixing skirting in vitrified tiles as per approved sample In skirting 4 inches height over 12 mm thick CM 1:4 backing as directed by Engineer- In charge. Basic Rate - Rs 65 per Sft. Make - RAK,Johnson,Kajaria. | F32: RAK | G32: Rft | H32: 75 | I32: 199 | J32: 14925 | K32: 75 | L32: ='Measurement Sheet'!J275 | N32: =K32*L32 | P32: =L32-I32 | Q32: =N32-J32 | R32: =IF(N32>J32,(N32-J32),0) | S32: =IF(N32<J32,(N32-J32),0) | T32: =S32+R32
A33: Non-Interior Work | B33: Non-Interior Works | C33: DISMANTLING AND DEMOLITION | D33: Existing old wall plaster Removal | E33: Dismantling of any existing Plaster from walls wherever required with necessary tools and tackels and carrying the debris away from site as per engineer- incharge instruction. | G33: Sft | H33: 7 | I33: 50 | J33: 350 | K33: 7 | N33: =K33*L33 | P33: =L33-I33 | Q33: =N33-J33 | R33: =IF(N33>J33,(N33-J33),0) | S33: =IF(N33<J33,(N33-J33),0) | T33: =S33+R33
A34: Main BOQ | B34: CIVIL WORKS | C34: FLOORING AND DADO | D34: Floor Protection Sheet | E34: Providing and applying covering on flooring for floor protection with polypropylene plastic bubble sheet. The rate should include the cleaning of floor covering on completion before handing over completed site as directed by Engineer - in charge. | F34: NA | G34: Sft | H34: 4 | I34: 1151 | J34: 4604 | K34: 4 | L34: ='Measurement Sheet'!J282 | N34: =K34*L34 | P34: =L34-I34 | Q34: =N34-J34 | R34: =IF(N34>J34,(N34-J34),0) | S34: =IF(N34<J34,(N34-J34),0) | T34: =S34+R34
A35: Main BOQ | B35: Carpentry Work | C35: FALSE-CELING | D35: Gypsum ceiling | E35: Providing and fixing Gypsum False Ceiling of India Gypsum or Saint Gobain make which includes G.I. Perimeter Channels of size 0.55mm thick, All steel sections to be marked with GYPSTEEL which is a registered trademark of IGL and hologram.[having One Flange of 20mm and another flange of 30mm and a web of 27mm] along with perimeter of ceiling, screw fixed to brick wall and partition with the help of Nylon sleeves and screws at 610mm centres. Then suspending G.I. intermediate channels of size 45mm [0.9mm thick with two flanges of 15mm each] from the soffit at 1220mm centres with ceiling angle of width 25mm X 10mm X 0.55mm thick fixed to soffit with G.I. cleat and steel expansion fasteners. Ceiling section of 0.55mm thick having knurled web of 51.5mm and two flanges of 26mm each with lips of 10.5mm are then fixed to the intermediate channel with the help of connecting clips and in direction perpendicular to the intermediate channel at 457 mm centres. 12.5mm tapered edge Gypboard [conforming to IS 2095-1982] is then screw fixed to ceiling section with 25mm dry wall Philips screws at 230mm centres. Screw fixing is done mechanically with drilling machine with suitable attachment. Finally tapered edges of the Gyp boards are to be jointed and finished so as to have a flush look which includes filling and finishing with jointing compound, joint paper tape and two coats of dry wall top coat suitable for Gypboard [as per recommended practice of India gypsum] etc complete as per the recommended practices of India Gypsum. Rate to be included all kinds of profiles and cut outs required for light fixtures, Speakers, Smoke detector, trap doors and AC grill in the ceiling. Rate quoted to include vertical drops [till 200mm ht] and all cut-outs required for light fixtures, smoke detectors and other services cut-outs complete as directed by Architect. Verticals above 200mm ht will be measured separately. | F35: Saint Gobain | G35: sft | H35: 90 | I35: 956 | J35: 86040 | K35: 90 | L35: ='Measurement Sheet'!J288 | N35: =K35*L35 | P35: =L35-I35 | Q35: =N35-J35 | R35: =IF(N35>J35,(N35-J35),0) | S35: =IF(N35<J35,(N35-J35),0) | T35: =S35+R35 | V35: Quantity Exceeded from the Work order project Manager Approval Required
A36: Non-Interior Work | B36: Non-Interior Works | C36: BRICK AND PLASTER WORKS | D36: PCC - Plain cement concrete | E36: Providing and laying of Plain cement concrete of grade M -10 [ 1:3:6 ] including shuttering for levelling course for flooring within the Bank Premise. The thickness may vary from 75mm to 100 mm as per requirement. [As per site condition - Prior approval of Bank required] | G36: Sft | H36: 48 | I36: 50 | J36: 2400 | K36: 48 | N36: =K36*L36 | P36: =L36-I36 | Q36: =N36-J36 | R36: =IF(N36>J36,(N36-J36),0) | S36: =IF(N36<J36,(N36-J36),0) | T36: =S36+R36
A37: Main BOQ | B37: CIVIL WORKS | C37: PLUMBING WORKS AND SANITARY FITTINGS | D37: Pantry Sink Bowl | E37: Providing and fixing in position stainless steel Single bowl kitchen sink of Nirali or Jindal make, along with S.S. waste coupling and Chrome bottle trap, Angle cock, 15mm dia 450mm long cold water connection pipe. etc complete. [ Sink Bowl Size : 21 x 18 ]. Make - Nirali or Jindal, Fitting - Jaquar Florentine series | F37: Jaquar | G37: Nos | H37: 6200 | I37: 1 | J37: 6200 | K37: 6200 | L37: ='Measurement Sheet'!J295 | N37: =K37*L37 | P37: =L37-I37 | Q37: =N37-J37 | R37: =IF(N37>J37,(N37-J37),0) | S37: =IF(N37<J37,(N37-J37),0) | T37: =S37+R37
A38: Main BOQ | B38: Carpentry Work | C38: FALSE-CELING | D38: Knauf Ceiling GRID [ARMSTRONG ] | E38: Providing and fixing modular Ceiling - CLASSIC LITE TEGULAR 15, modular ceiling systems with T- 15 GRID with 16 mm Thick mineral fibre board ceiling tiles as per following specifications. suspension system shall be manufacturer specification. Rate to include all fastening accessories with approved finishes. The last hanger at the end of each main runner should not be greater than 600 mm from the adjacent wall. Ceiling tiles shall be approved make TEGULAR edge tiles, of size 600 mm x 600 mm of approved colour. Armstrong make, Tile-RH99, 0.55 NRC, 16mm thick tile, 2ftx2ft size, with Knauf Ceiling [Armstrong] T- frame. | F38: Knauf | G38: sft | H38: 115 | I38: 395 | J38: 45425 | K38: 115 | L38: ='Measurement Sheet'!J319 | N38: =K38*L38 | P38: =L38-I38 | Q38: =N38-J38 | R38: =IF(N38>J38,(N38-J38),0) | S38: =IF(N38<J38,(N38-J38),0) | T38: =S38+R38 | V38: Quantity Exceeded from the Work order project Manager Approval Required
A39: Non-Interior Work | B39: Non-Interior Works | C39: BRICK AND PLASTER WORKS | D39: Chasing floor- wall for electrical trunking | E39: Chasing in existing brick or siporex up to 200mm wide and 75mm deep, for installation of A.C. copper pipes and drain pipes as required and making good of chases with cement plaster or POP ready for application of paint. | F39: NA | G39: Rft | H39: 40 | I39: 200 | J39: 8000 | K39: 40 | L39: ='Measurement Sheet'!J325 | N39: =K39*L39 | P39: =L39-I39 | Q39: =N39-J39 | R39: =IF(N39>J39,(N39-J39),0) | S39: =IF(N39<J39,(N39-J39),0) | T39: =S39+R39
A40: Non-Interior Work | B40: Non-Interior Works | C40: BRICK AND PLASTER WORKS | D40: Sill-lining with Red - Black granite at toilet door sill &frame | E40: Providing and laying of Sill, jambs to windows and Doors frame in required positions Approved Red or black granite of 18mm thk. Upto 2100mm in length [double piece], of approved make &color with machine, cut and machine polish up to 150mm wide, in cement mortar of 1:3 for sills and jambs of windows .The rate is inclusive of full rounded moulding at the edges from inside. | F40: NA | G40: Rft | H40: 275 | I40: 253 | J40: 69575 | K40: 275 | L40: ='Measurement Sheet'!J338 | N40: =K40*L40 | P40: =L40-I40 | Q40: =N40-J40 | R40: =IF(N40>J40,(N40-J40),0) | S40: =IF(N40<J40,(N40-J40),0) | T40: =S40+R40
...

Sheet Measurement Sheet
A1: SR NO | B1: SUB CATEGORY | C1: Particulars | D1: UNIT | E1: BOQ Qty | F1: DIMENSION | J1: QTY | K1: Photographic Dimension | O1: QTY | P1: REMRAKS
F2: Nos | G2: L | H2: B | I2: D/H | K2: Nos | L2: L | M2: B | N2: D/H
A4: 1 | B4: Diesel for DG | C4: Reimbursement of Diesel for DG | D4: L.sum | E4: 1
J5: =PRODUCT(F5:I5)
C6: Bill Attached | D6: L/s | F6: 1 | J6: =PRODUCT(F6:I6) | K6: 1 | P6: Bill required
J7: =PRODUCT(F7:I7)
C8: Total Qty | J8: =SUM(J5:J7)
A10: =A4+1 | B10: Softboard in Managers cabin-cubicle , 5S and Customer area Notice Board | C10: Providing and fixing soft board incl of 6mm ply base backing and 12mm thk. crock sheet which is wrapped all around with fabric [Burgandy for regular office areas and royal blue for Private banking].The edge trims to be finished in 19mmx 6mm lipping p | D10: Sft | E10: 60
J11: =PRODUCT(F11:I11)
C12: Branch Area - Wall | D12: Sq.ft | F12: 1 | G12: 5 | I12: 4 | J12: =PRODUCT(F12:I12) | K12: 1
C13: JL Cabin - Wall | D13: Sq.ft | F13: 1 | G13: 3.25 | I13: 4 | J13: =PRODUCT(F13:I13) | K13: 1
C14: ATM Area - Wall | D14: Sq.ft | F14: 1 | G14: 4 | I14: 3 | J14: =PRODUCT(F14:I14) | K14: 1
C15: BM Cabin - Table | D15: Sq.ft | F15: 1 | G15: 3.5 | I15: 1.5 | J15: =PRODUCT(F15:I15) | K15: 1
J16: =PRODUCT(F16:I16)
C17: Total Qty | J17: =ROUND(SUM(J11:J16),)
A19: =A10+1 | B19: Rubber Mat in UPS room | C19: Rubber Mat in UPS room, 20mm thickness. | D19: Sft | E19: 27
C20: Electrical Room | J20: =PRODUCT(F20:I20)
C21: Floor Area | D21: Sq.ft | F21: 1 | G21: 8.33 | I21: 3.5 | J21: =PRODUCT(F21:I21) | K21: 1
J22: =PRODUCT(F22:I22)
C23: Total Qty | J23: =ROUND(SUM(J20:J22),)
A25: =A19+1 | B25: Master Switch | C25: Provision and installation of master switch nearest to the entrance of the premises, as per the specifications. | D25: Nos | E25: 1
C26: Branch Area | J26: =PRODUCT(F26:I26)
C27: Master Switch | D27: Nos | F27: 1 | J27: =PRODUCT(F27:I27) | K27: 1
J28: =PRODUCT(F28:I28)
C29: Total Qty | J29: =ROUND(SUM(J26:J28),)
A31: =A25+1 | B31: ATM backdrop | C31: ATM wall design in Grey and white with 40mm commercial ply and laminate in high gloss finish and Rehau make edge banding as per approve design. Rs.7000 for one ATM and Rs.5000 for every additional machines. Quantity not to exceed 1 no. per site. | D31: Nos | E31: 1
C32: ATM Area | J32: =PRODUCT(F32:I32)
C33: 1st ATM Wall design | D33: Nos | F33: 1 | J33: =PRODUCT(F33:I33) | K33: 1
J34: =PRODUCT(F34:I34)
C35: Total Qty | J35: =ROUND(SUM(J32:J34),)
A37: =A31+1 | B37: ATM Backdrop for additional machines | C37: ATM wall design in Grey and white with 40mm commercial ply and laminate in high gloss finish and Rehau make edge banding as per approve design, for every additional machines | D37: Nos | E37: 1
C38: ATM Area | J38: =PRODUCT(F38:I38)
C39: 2nd ATM Wall design | D39: Nos | F39: 1 | J39: =PRODUCT(F39:I39) | K39: 1
J40: =PRODUCT(F40:I40)
C41: Total Qty | J41: =ROUND(SUM(J38:J40),)
A43: =A37+1 | B43: Wall Mounted Fan | C43: Providing and fixing wall mounted metal FAN 18 inch make orient, havells and almourd.orient, havells and almounard | D43: nos | E43: 2 | P43: Not provided
C44: Strong Room | J44: =PRODUCT(F44:I44)
C45: Wall Fan | D45: Nos | F45: 1 | J45: =PRODUCT(F45:I45) | K45: 1
C46: Pantry Area
C47: Wall Fan | D47: Nos | F47: 1 | J47: =PRODUCT(F47:I47) | K47: 1
...

Sheet PM Approval
G1: As per WO | J1: As per CWI | M1: Variance | O1: CWI Remark | P1: Remark | Q1: PM Approval
A2: TYPE | B2: NATURE OF WORK | C2: CATEGORY | D2: SUB CATEGORY | E2: Particulars | F2: UNIT | G2: RATE | H2: QTY | I2: AMOUNT | J2: RATE | K2: QTY | L2: AMOUNT | M2: QTY | N2: AMOUNT
A3: Reimbursable Items | B3: Electricity &Diesel Expenses to TKO | C3: Electricity &Diesel Expenses to TKO | D3: Diesel for DG | E3: Reimbursement of Diesel for DG | F3: L.sum | G3: 3000 | H3: 1 | I3: 3000 | J3: 3600 | K3: 1 | L3: 3600 | M3: 0 | N3: 600 | P3: Quantity Exceeded from the Work order project Manager Approval Required
A4: Main BOQ | B4: Carpentry Work | C4: MISCELLANEOUS | D4: Rubber Mat in UPS room | E4: Rubber Mat in UPS room, 20mm thickness. | F4: Sft | G4: 140 | H4: 27 | I4: 3780 | J4: 140 | K4: 29 | L4: 4060 | M4: 2 | N4: 280 | P4: Quantity Exceeded from the Work order project Manager Approval Required
A5: Main BOQ | B5: Carpentry Work | C5: MISCELLANEOUS | D5: Lacqured Glass new | E5: Providing and fixing Lacqured glass in Fusion Orange colour for Theme wall. Make - Saint Gobain, Asahi | F5: sqft | G5: 525 | H5: 56 | I5: 29400 | J5: 525 | K5: 84 | L5: 44100 | M5: 28 | N5: 14700 | P5: Quantity Exceeded from the Work order project Manager Approval Required
A6: Main BOQ | B6: CIVIL WORKS | C6: FLOORING AND DADO | D6: Brick Bat Coba in Toilet Area | E6: Providing and laying of raised floor upto 200mm ht with necessary Brick bat coba - Waste water lines to be encased with 1:3:6 grade concrete and applying brick bat coba [1:6 mortar], The mortar for the brick- bat coba filling shall be CM 1:4 and admixed with integral waterproofing compound, curing, complete. curing 2 days and then finishing the surface with 10 mm thk of 1:6 mortar to proper level and slope. Rate to include necessary steps and ramp as per architects and clients instructions. | F6: Sft | G6: 75 | H6: 77 | I6: 5775 | J6: 75 | K6: 90 | L6: 6750 | M6: 13 | N6: 975 | P6: Quantity Exceeded from the Work order project Manager Approval Required
A7: Main BOQ | B7: Carpentry Work | C7: DOORS AND WINDOWS | D7: Fixed Glazing | E7: Providing and fixing full height partition using 12mm thick toughened glass with top &bottom C Channel etc. complete. The glass edges shall be polish on all sides. The entire fixed partition shall be errected in complete line &level. as per instruction of Architect or Bank including other arrangement for necessary support. Make - Saint Gobain glass or Asahi or Modiguard | F7: sft | G7: 450 | H7: 469 | I7: 211050 | J7: 450 | K7: 502 | L7: 225900 | M7: 33 | N7: 14850 | P7: Quantity Exceeded from the Work order project Manager Approval Required
A8: Main BOQ | B8: Carpentry Work | C8: DOORS AND WINDOWS | D8: Main Entrance doors for Branch and ATM | E8: Providing and fixing Single Shutter, 12mm thick toughened glass of size 1050 x 2100mm and approved make as shutters on patch fittings of specified make, floor spring, Handle of 12 inch long x 4inch bended width with 1inch outer Diameter, Inculding all other accssories, hard ware etc. complete [Floor Mounted Floor Spring from Dorma BTS75], Make - Saint Gobain glass or Asahi or Modiguard with Dorma Accessories | F8: nos | G8: 28500 | H8: 1 | I8: 28500 | J8: 28500 | K8: 2 | L8: 57000 | M8: 1 | N8: 28500 | P8: Quantity Exceeded from the Work order project Manager Approval Required
A9: Main BOQ | B9: Carpentry Work | C9: DOORS AND WINDOWS | D9: Low Height Door for Teller | E9: Providing &fixing door as per design &size and including Godrej tribolt latch lock. Size of door to match the height of side partition. [approx 5ft x 2ft-6 ] | F9: nos | G9: 5500 | H9: 1 | I9: 5500 | J9: 5500 | K9: 2 | L9: 11000 | M9: 1 | N9: 5500 | P9: Quantity Exceeded from the Work order project Manager Approval Required
A10: Main BOQ | B10: CIVIL WORKS | C10: FLOORING AND DADO | D10: Vitrified Tile for Flooring | E10: Providing and fixing of vitrified tiles of minimum 600x600mm size confirming to IS 15622 of approved make in all colors and shades approved by Engineer-in-charge including 12-15mm thick base coat of cement mortar 1:4 [ using coarse river sand ] and jointing with grey cement slurry @ 3.3 kg per sq.m including pointing with white cement based tile grout of approved make of matching shade complete as per patterns, drawings and specifications all as directed by Engineer-in-charge. Basic Rate - Rs 60 per Sft. Make- RAK,Johnson,Kajaria | F10: Sft | G10: 130 | H10: 127 | I10: 16510 | J10: 130 | K10: 140 | L10: 18200 | M10: 13 | N10: 1690 | P10: Quantity Exceeded from the Work order project Manager Approval Required
A11: Main BOQ | B11: CIVIL WORKS | C11: FLOORING AND DADO | D11: Vitrified Tile for Flooring 80x80 | E11: Providing and fixing of vitrified tiles of minimum 800x800mm size confirming to IS 15622 of approved make in all colors and shades approved by Engineer-in-charge including 12-15mm thick base coat of cement mortar 1:4 [ using coarse river sand ] and jointing with grey cement slurry @ 3.3 kg per sq.m including pointing with white cement based tile grout of approved make of matching shade complete as per patterns, drawings and specifications all as directed by Engineer-in-charge. Basic Rate - Rs 75per Sft. Make - Johnson,RAK,Kajaria | F11: Sft | G11: 145 | H11: 861 | I11: 124845 | J11: 145 | K11: 891 | L11: 129195 | M11: 30 | N11: 4350 | P11: Quantity Exceeded from the Work order project Manager Approval Required
A12: Main BOQ | B12: Carpentry Work | C12: FALSE-CELING | D12: Gypsum ceiling | E12: Providing and fixing Gypsum False Ceiling of India Gypsum or Saint Gobain make which includes G.I. Perimeter Channels of size 0.55mm thick, All steel sections to be marked with GYPSTEEL which is a registered trademark of IGL and hologram.[having One Flange of 20mm and another flange of 30mm and a web of 27mm] along with perimeter of ceiling, screw fixed to brick wall and partition with the help of Nylon sleeves and screws at 610mm centres. Then suspending G.I. intermediate channels of size 45mm [0.9mm thick with two flanges of 15mm each] from the soffit at 1220mm centres with ceiling angle of width 25mm X 10mm X 0.55mm thick fixed to soffit with G.I. cleat and steel expansion fasteners. Ceiling section of 0.55mm thick having knurled web of 51.5mm and two flanges of 26mm each with lips of 10.5mm are then fixed to the intermediate channel with the help of connecting clips and in direction perpendicular to the intermediate channel at 457 mm centres. 12.5mm tapered edge Gypboard [conforming to IS 2095-1982] is then screw fixed to ceiling section with 25mm dry wall Philips screws at 230mm centres. Screw fixing is done mechanically with drilling machine with suitable attachment. Finally tapered edges of the Gyp boards are to be jointed and finished so as to have a flush look which includes filling and finishing with jointing compound, joint paper tape and two coats of dry wall top coat suitable for Gypboard [as per recommended practice of India gypsum] etc complete as per the recommended practices of India Gypsum. Rate to be included all kinds of profiles and cut outs required for light fixtures, Speakers, Smoke detector, trap doors and AC grill in the ceiling. Rate quoted to include vertical drops [till 200mm ht] and all cut-outs required for light fixtures, smoke detectors and other services cut-outs complete as directed by Architect. Verticals above 200mm ht will be measured separately. | F12: sft | G12: 90 | H12: 956 | I12: 86040 | J12: 90 | K12: 971 | L12: 87390 | M12: 15 | N12: 1350 | P12: Quantity Exceeded from the Work order project Manager Approval Required
A13: Main BOQ | B13: Carpentry Work | C13: FALSE-CELING | D13: Knauf Ceiling GRID [ARMSTRONG ] | E13: Providing and fixing modular Ceiling - CLASSIC LITE TEGULAR 15, modular ceiling systems with T- 15 GRID with 16 mm Thick mineral fibre board ceiling tiles as per following specifications. suspension system shall be manufacturer specification. Rate to include all fastening accessories with approved finishes. The last hanger at the end of each main runner should not be greater than 600 mm from the adjacent wall. Ceiling tiles shall be approved make TEGULAR edge tiles, of size 600 mm x 600 mm of approved colour. Armstrong make, Tile-RH99, 0.55 NRC, 16mm thick tile, 2ftx2ft size, with Knauf Ceiling [Armstrong] T- frame. | F13: sft | G13: 115 | H13: 395 | I13: 45425 | J13: 115 | K13: 403 | L13: 46345 | M13: 8 | N13: 920 | P13: Quantity Exceeded from the Work order project Manager Approval Required
A14: Main BOQ | B14: Carpentry Work | C14: STORAGE UNITS AND COUNTERS | D14: Over Head Storage | E14: Providing and Fabrication of Over head storage of upto 450mm depth and 900mm height as per details. Shutters, top, bottom, intermediates and shelves to be made out of 18mm Marine ply with PVC edges banding and 12mm marine ply back. All the exposed surface finished with 1mm thk laminate and inside finished with 0.8mm laminate. Shutters to be fixed with all necessary accessories like hinges, ball catches, tower bolts, locks, and handles etc.as directed by architect. Provide adjustable shelf formed of ply finished with 0.8mm laminate. Ply make- conforming to IS: 303 [Century, Greenply, Samrat ]Laminate - Merino, Century, Greenlam, Samrat.Base rate of laminate:Rs.50 per sft | F14: sft | G14: 850 | H14: 14 | I14: 11900 | J14: 850 | K14: 47 | L14: 39950 | M14: 33 | N14: 28050 | P14: Quantity Exceeded from the Work order project Manager Approval Required
... A25: Main BOQ | B25: CIVIL WORKS | C25: FLOORING AND DADO | D25: Kota Stone Flooring | E25: Providing and laying approved size Size 600mm X 600mm 19 mm thk machine cut machine polished Kota Stones over 20mm thk cement mortar in the ratio of 1:6 [1 cement : 6 Crushed sand] including cleaning and preparing the surface forbedding, spreading neat cement slurry by using cement at 2Kg per SQM prior to bedding and spreading cement paste using min cement @ 4.5Kg per SQM over bedding, cleaning of joints, grouting with approved quality matching color grout, etc complete as directed. for Safe room, Strong room, locker room and other areas as per site engineer instructions. | F25: Sft | G25: 160 | H25: 170 | I25: 27200 | J25: 160 | K25: 176 | L25: 28160 | M25: 6 | N25: 960 | P25: Quantity Exceeded from the Work order project Manager Approval Required
A26: Main BOQ | B26: Carpentry Work | C26: DOORS AND WINDOWS | D26: Sliding door | E26: Providing and fixing sliding door of size 3ft-0 x 7ft-0 and made up of 32 mm blockboard or Ply finished in on both sides with the laminate as per the approved sample. incl of flushed steel handle of approved make as per details including all necessary accessories. Ply make- conforming to IS: 303 [Century, Greenply, Samrat] Make - Saint Gobain glass or Asahi or Modiguard Laminate - Merino, Century, Greenlam, Samrat.Base rate of laminate:Rs.50sft, Hardware : Dorma, Ozone, Hafele | F26: nos | J26: 11000 | K26: 1 | L26: 11000 | M26: 1 | N26: 11000 | O26: Rate Approval required | P26: Quantities Not in Work order Project Manager Approval required
A27: Non Standard | B27: Carpentry Work | C27: MISCELLANEOUS | D27: Corner Guard | E27: Corner Guard | F27: Rft | J27: 65 | K27: 123 | L27: 7995 | M27: 123 | N27: 7995 | O27: Rate Approval required | P27: Quantities Not in Work order Project Manager Approval required
A28: Non-Standard | B28: Carpentry Work | C28: Carpentry Work | D28: Pantry Table | E28: Providing & fixing the Pantry Table with MS Base, used in 25mm thick ply with both side laminet with top edge 2mm thik banding, MS Base with powder coated as per details given. ( Size - 4' x 3' ) | F28: Nos | J28: 12500 | K28: 1 | L28: 12500 | M28: 1 | N28: 12500 | O28: Rate Approval required | P28: Quantities Not in Work order Project Manager Approval required
A29: Main BOQ | B29: Carpentry Work | C29: PARTITIONS AND PANELLING | D29: ATM Door Back Room | E29: ATM back room door - Providing and fixing ATM back room door, made of 25mm commercial ply or HDHMR boards finished in 1mm high gloss laminate, with lock, magnet and all fittings, as per approved design. Ply make- Century, Greenply, Kitply. Laminate | F29: Sft | J29: 300 | K29: 14 | L29: 4200 | M29: 14 | N29: 4200 | O29: Rate Approval required | P29: Quantities Not in Work order Project Manager Approval required
A30: Main BOQ | B30: CIVIL WORKS | C30: FLOORING AND DADO | D30: External Flooring in Granite | E30: Supply and Laying of 18mm thk machine cut, machine polished [Ruby red]granite flooring, on a pre-finished surface with 60mm cement sand mortar in 1:4 Ratio with required adhesive, in approved design and pattern. The rates shall be inclusive of machine polishing edges in case of protruding edges & groove or chamfering. Rate to include for laying to the pattern as directed by Architect including floor preparation. Granite - Ruby Red or Bruno Red or RBI Red - Basic Rate Rs 150 per Sft | F30: Sft | J30: 350 | K30: 43 | L30: 15050 | M30: 43 | N30: 15050 | O30: Rate Approval required | P30: Quantities Not in Work order Project Manager Approval required
A31: Main BOQ | B31: Carpentry Work | C31: LOOSE FURNITURE | D31: Writing Ledge 33 inch X18 inch Glass top ALLEN Model | E31: Writing Ledge [Allen Model]Providing writing ledge with framework in ply and finished in Laminate and top of 12mm thick glass with beveled edges as per the design.Ply make- Century, Green ply, Samrat.MDF Make - Merino, Century, Greenpanel.Laminate - Merino, Century, Greenlam, Aica sunmica, Base rate of laminate:Rs.50 per sft | F31: nos | J31: 5500 | K31: 1 | L31: 5500 | M31: 1 | N31: 5500 | O31: Rate Approval required | P31: Quantities Not in Work order Project Manager Approval required
A32: Non-Interior Work | B32: Non-Interior Works | C32: BRICK AND PLASTER WORKS | D32: MS Grill work for Strong Room Ceiling - applicable only in case no RCC is possible for ceiling | E32: Providing, Fabricating and erecting of MS grills exposed on internal wall surface and ceiling consisting in 20 sq. mm MS Bars spaced 75 mm centre to centre in angle iron frame tightly bolted on ceiling and floor and finished in Black colored enamel paint. | F32: Sft | J32: 800 | K32: 90 | L32: 72000 | M32: 90 | N32: 72000 | O32: Rate Approval required | P32: Quantities Not in Work order Project Manager Approval required
A33: Non Standard | B33: Non-Interior Works | C33: METAL-WORK | D33: Ms Staircase | E33: MS Sataircase | F33: L/s | J33: 70000 | K33: 1 | L33: 70000 | M33: 1 | N33: 70000 | O33: Rate Approval required | P33: Quantities Not in Work order Project Manager Approval required
A34: Main BOQ | B34: Carpentry Work | C34: LOOSE FURNITURE | D34: Pedestal unit E10 | E34: Providing and fixing pedestal units as per design - 400x450x650mm [WxDxH] with 3 drawers in Metabox Sections. All hinges and side telescopic channels to be considered are of compacted and of EBCO or Al-Bihari make. All the drawers to have individual locks. Ply make- Century, Green ply, Samrat. MDF Make - Merino, Century, Greenpanel Laminate - Merino, Century, Greenlam, Aica sunmica, Base rate of laminate:Rs.50 per sft | F34: nos | J34: 5000 | K34: 6 | L34: 30000 | M34: 6 | N34: 30000 | O34: Rate Approval required | P34: Quantities Not in Work order Project Manager Approval required
A35: Non-Interior Work | B35: Non-Interior Works | C35: BRICK AND PLASTER WORKS | D35: 9 inch thick walls in Siporex with both side plaster | E35: Providing and constructing 9inch thick masonry at all levels with approved quality Siporex [confirming to IS 12894] in cement mortar 1:4 [1 cement : 4 River Sand] uniformly mixed in machine with approved non-shrinking compound as per manufacturers instruction in specified courses of approved bond , required formwork, complete including pointing, raking out joints, curing, cleaning, including independent double legged MS tubular scaffolding, at all heights, depths and leads, dewatering area where required etc., a Providing 6 mm thick Plain Internal Plastering in cement mortar 1:4 [using fine river sand] finished smooth, including sieving of sand to required fineness, preparation of the surface, scaffolding, curing all as per specifications, drawings and as directed at site etc. complete as per specifications as directed by Engineer-in-charge. | F35: Sft | J35: 180 | K35: 32 | L35: 5760 | M35: 32 | N35: 5760 | O35: Rate Approval required | P35: Quantities Not in Work order Project Manager Approval required
A36: Non-Interior Work | B36: Non-Interior Works | C36: BRICK AND PLASTER WORKS | D36: 9 inch thk. RCC for Strong Room walls with both side plaster | E36: R.C.C work -Providing and casting in-situ reinforced cement concrete 225 mm thick for wall, columns as per details drawings and design.The rate to include cost of re-baring Hilti and drilling and joining with existing beam or lintel including shuttering, steel , concrete, inserts, cutout for ventilator, hacking, curing, bonding chemical or slurry all complete, design and certification from structural consultant. Grade of concrete to be considered shall be M25 and steel to be considered as 12mm dia tor steel @150mm centre to centre both way in two layers staggered by 75mm in both directions. The thickness of walls to be 225 mm without plaster. 300mm - 300mm RCC column to be provided near the strong room door for mounting strong room door. Rate is inclusive of plaster on both side of wall. | F36: Cft | J36: 625 | K36: 484 | L36: 302500 | M36: 484 | N36: 302500 | O36: Rate Approval required | P36: Quantities Not in Work order Project Manager Approval required
A37: Non Standard | B37: Non-Interior Works | C37: PARTITIONS AND PANELLING | D37: Ply Panelling | E37: Providing & fixing Ply Panelling for Staircase & ATM Ceiling | F37: Sq.ft | J37: 185 | K37: 181 | L37: 33485 | M37: 181 | N37: 33485 | O37: Rate Approval required | P37: Quantities Not in Work order Project Manager Approval required
... A40: Non Standard | B40: Non-Interior Works | C40: DOORS AND WINDOWS | D40: Aluminium Door Frame 50mmx 38mm ( Door Size - 1050 x 2400mm ) | E40: Aluminium Door Frame 50mmx 38mm ( Door Size - 1050 x 2400mm ) | F40: Nos | J40: 10000 | K40: 2 | L40: 20000 | M40: 2 | N40: 20000 | O40: Rate Approval required | P40: Quantities Not in Work order Project Manager Approval required

Sheet SUMMARY
A1: Client : ICICI Bank Ltd,
A2: Project : ICICI Bank Ltd - Chaphekar, Chowk, Pune
A3: Location : Chaphekar, Chowk, Pune
A4: TKO Name: Bella inter décor
A5: PO No.: POCap-318369
A6: PO Date: 21/06/2025
A8: Cost of Summary
A10: DESCRIPTION | B10: P ORDER AMOUNT | C10: FINAL BILL AMOUNT | D10: REMARKS
A11: CIVIL WORKS | B11: =SUMIF(BOQ!B:B,SUMMARY!A11,BOQ!J:J) | C11: =SUMIF(BOQ!B:B,SUMMARY!A11,BOQ!N:N)
A12: Carpentry Work | B12: =SUMIF(BOQ!B:B,SUMMARY!A12,BOQ!J:J) | C12: =SUMIF(BOQ!B:B,SUMMARY!A12,BOQ!N:N)
A13: Electrical Works | B13: =SUMIF(BOQ!B:B,SUMMARY!A13,BOQ!J:J) | C13: =SUMIF(BOQ!B:B,SUMMARY!A13,BOQ!N:N)
A14: Non-Interior Works | B14: =SUMIF(BOQ!B:B,SUMMARY!A14,BOQ!J:J) | C14: =SUMIF(BOQ!B:B,SUMMARY!A14,BOQ!N:N)
A15: Electricity &Diesel Expenses to TKO | B15: =SUMIF(BOQ!B:B,SUMMARY!A15,BOQ!J:J) | C15: =SUMIF(BOQ!B:B,SUMMARY!A15,BOQ!N:N)
A16: Reimbursement of Vendor Elements | B16: =SUMIF(BOQ!B:B,SUMMARY!A16,BOQ!J:J) | C16: =SUMIF(BOQ!B:B,SUMMARY!A16,BOQ!N:N)
C17: =SUMIF(BOQ!B:B,SUMMARY!A17,BOQ!N:N)
A18: SUB TOTAL AMOUNT | B18: =SUM(B11:B17) | C18: =SUM(C11:C17)
C19: =B18-C18

Sheet Summary Sheet
A1: Sr.No. | B1: Particulars | C1: As per WO Amount (Rs) | D1: As Per CWI Amount (Rs) | E1: Excess | F1: Saving | G1: Total
A2: I | B2: CIVIL WORKS | C2: 497698 | D2: 461298 | E2: 23340 | F2: -59740 | G2: -36400
A3: II | B3: Carpentry Work | C3: 1762843 | D3: 2010248 | E3: 514185 | F3: -266780 | G3: 247405
A4: III | B4: Electrical Works | C4: 545400 | D4: 545400 | E4: 0 | F4: 0 | G4: 0
A5: IV | B5: Non-Interior Works | C5: 266410 | D5: 768740 | E5: 611915 | F5: -109585 | G5: 502330
A6: V | B6: Electricity &Diesel Expenses to TKO | C6: 3000 | D6: 3600 | E6: 600 | F6: 0 | G6: 600
A7: VI | B7: Reimbursement of Vendor Elements | C7: 30000 | D7: 5000 | E7: 0 | F7: -25000 | G7: -25000
A8: VII
A9: VIII
A10: A | B10: TOTAL | C10: 3105351 | D10: 3794286 | E10: 1150040 | F10: -461105 | G10: 688935
A11: TAXES | B11: TAXES:
B12: Taxes as applicable (pl indicate applicable taxes)
A13: a)
A14: b) | C14: 279481.59 | D14: 341485.74 | E14: 103503.6 | F14: -41499.45 | G14: 62004.15
A15: c) | C15: 279481.59 | D15: 341485.74 | E15: 103503.6 | F15: -41499.45 | G15: 62004.15
A17: B | B17: Total | C17: 558963.18 | D17: 682971.48 | E17: 207007.2 | F17: -82998.9 | G17: 124008.3
A19: (A + B) | B19: Grand Total (incl. taxes) | C19: 3664314.2 | D19: 4477257.5 | E19: 1357047.2 | F19: -544103.9 | G19: 812943.3
