Workbook
Name _GoBack: #REF!
Name Excel_BuiltIn_Print_Titles_13: '[1]extra work elec bill '!#REF!

Sheet CWI Summary
A1: Summary For Ichalkarnji, Kolhapur
A3: Address | B3: HDFC Bank Ltd. Upper Ground Floor & first floor ,12/215,Bungalow Road, Ichalkarnji,Tal- Hatkanagale,Dist -Kolhapur - 416115.
A4: Contractor | B4: M/s. Teamswift Projects Pvt Ltd
A5: Area | B5: 2,280 Sqft
A6: LOC, Code | B6: 0736
A7: PO No | B7: CPC/014849/25-26
A8: FINAL BILL SUMMARY
A9: Sr. No | B9: Particulars | C9: AS per WO | D9: As per CWI | E9: Excess | F9: Saving | G9: Total
A10: I | B10: Civil & related works | C10: =BOQ!$F$200 -> 1504620 | D10: =BOQ!$I$200 -> 1444213.2 | E10: =BOQ!L200 -> 102419.15 | F10: =BOQ!M200 -> -162825.93 | G10: =BOQ!N200 -> -60406.78
A11: II | B11: POP and false ceiling work | C11: =BOQ!$F$217 -> 324120 | D11: =BOQ!$I$217 -> 295074.12 | E11: =BOQ!L217 -> 21427.64 | F11: =BOQ!M217 -> -50473.52 | G11: =BOQ!N217 -> -29045.88
A12: III | B12: Carpentry and Interior work | C12: =BOQ!$F$456 -> 2147140 | D12: =BOQ!$I$456 -> 1999427.6 | E12: =BOQ!L456 -> 364478.61 | F12: =BOQ!M456 -> -512191.02 | G12: =BOQ!N456 -> -147712.41
A13: IV | B13: Painting works | C13: =BOQ!$F$481 -> 69930 | D13: =BOQ!$I$481 -> 79262 | E13: =BOQ!L481 -> 31362.25 | F13: =BOQ!M481 -> -22030.25 | G13: =BOQ!N481 -> 9332
A14: V | B14: Rolling Shutter and MS Work | C14: =BOQ!$F$509 -> 28800 | D14: =BOQ!$I$509 -> 0 | E14: =BOQ!L509 -> 0 | F14: =BOQ!M509 -> -28800 | G14: =BOQ!N509 -> -28800
A15: VI | B15: Electrification and Allied Work | C15: =BOQ!$F$1148 -> 1106859 | D15: =BOQ!$I$1148 -> 793654.56 | E15: =BOQ!L1148 -> 105439 | F15: =BOQ!M1148 -> -418643.44 | G15: =BOQ!N1148 -> -313204.44
A16: VII | B16: Additional Work | C16: =BOQ!$F$1163 -> 0 | D16: =BOQ!$I$1163 -> 162810.6 | E16: =BOQ!L1163 -> 162810.6 | F16: =BOQ!M1163 -> 0 | G16: =BOQ!N1163 -> 162810.6
A17: A | B17: TOTAL | C17: =SUM(C10:C16) -> 5181469 | D17: =SUM(D10:D16) -> 4774442.1 | E17: =SUM(E10:E16) -> 787937.25 | F17: =SUM(F10:F16) -> -1194964.2 | G17: =SUM(G10:G16) -> -407026.91
A18: TAXES | B18: TAXES:
B19: Taxes as applicable (pl indicate applicable taxes)
A20: a) | B20: CGST @ 9% | C20: =C17*9% -> 466332.21 | D20: =D17*9% -> 429699.79 | E20: =E17*9% -> 70914.352 | F20: =F17*9% -> -107546.77 | G20: =G17*9% -> -36632.422
A21: b) | B21: SGST @ 9% | C21: =C17*9% -> 466332.21 | D21: =D17*9% -> 429699.79 | E21: =E17*9% -> 70914.352 | F21: =F17*9% -> -107546.77 | G21: =G17*9% -> -36632.422
A22: c)
A24: B | B24: Total | C24: =SUM(C19:C23) -> 932664.42 | D24: =SUM(D19:D23) -> 859399.58 | E24: =SUM(E20:E23) -> 141828.7 | F24: =SUM(F19:F23) -> -215093.55 | G24: =SUM(G19:G23) -> -73264.844
A26: (A + B) | B26: Grand Total (incl. taxes) | C26: =C17+C24 -> 6114133.4 | D26: =D17+D24 -> 5633841.7 | E26: =SUM(E19:E25) -> 283657.41 | F26: =SUM(F19:F25) -> -430187.1 | G26: =SUM(G19:G25) -> -146529.69

Sheet Extracted Data
A1: U. Code | B1: Sub Category | C1: Nature of Works | D1: Particulars | E1: Rate | F1: As per CWI (Qty) | G1: As per CWI (Amount) | H1: Rate per sq.feet | I1: Unit
A2: Sr. No | B2: Others | C2: Others/Uncategorized | D2: Particulars | E2: 0 | F2: 0 | G2: 0 | H2: 0 | I2: Unit
A3: I | B3: Others | C3: Others/Uncategorized | D3: CIVIL & RELATED WORKS | E3: 0 | F3: 0 | G3: 0 | H3: 0
A4: 1 | B4: Others | C4: Others/Uncategorized | D4: Demolition / Clearing Works | E4: 0 | F4: 0 | G4: 0 | H4: 0
A5: a | B5: Others | C5: Others/Uncategorized | D5: Dismantling/Demolishing the following and carting away the debris from the site and unloading at a approved location as per statutory rules and regulations. | E5: 0 | F5: 0 | G5: 0 | H5: 0
A6: i | B6: Others | C6: Others/Uncategorized | D6: Dismantling of existing brickwork | E6: 12 | F6: 0 | G6: 0 | H6: 0 | I6: Sq.ft
A7: ii | B7: POP Punning | C7: POP & FALSE CEILING WORKS | D7: Dismantling of existing dado tiles without plaster | E7: 11 | F7: 932.39 | G7: 10256.29 | H7: 4.5 | I7: Sq.ft
A8: iii | B8: Partition | C8: CARPENTRY AND INTERIOR WORKS | D8: Dismantling of existing plaster | E8: 11 | F8: 459.73 | G8: 5057.03 | H8: 2.22 | I8: Sq.ft
A9: iv | B9: PAINTING WORKS | C9: PAINTING WORKS | D9: Existing flooring including bedding material & PCC/IPS. | E9: 16 | F9: 540.83 | G9: 8653.28 | H9: 3.8 | I9: Sq.ft
A10: v | B10: ROLLING SHUTTER AND MS WORK | C10: ROLLING SHUTTER AND MS WORK | D10: Existing Doors / Windows | E10: 381 | F10: 16 | G10: 6096 | H10: 2.67 | I10: Nos.
A11: vi | B11: ELECTRIFICATION AND ALLIED WORKS | C11: ELECTRIFICATION AND ALLIED WORKS | D11: Dismantling of existing Sanitary wares & Plumbing Fittings | E11: 1199 | F11: 0 | G11: 0 | H11: 0 | I11: Nos.
A12: vii | B12: ELECTRIFICATION AND ALLIED WORKS | C12: ELECTRIFICATION AND ALLIED WORKS | D12: Existing Rolling Shutter , Safety door, collapsible door etc. | E12: 11 | F12: 0 | G12: 0 | H12: 0 | I12: Sq.ft
A13: viii | B13: ELECTRIFICATION AND ALLIED WORKS | C13: ELECTRIFICATION AND ALLIED WORKS | D13: Existing Electrical fittings and fixtures | E13: 3 | F13: 0 | G13: 0 | H13: 0 | I13: Sq.ft
A14: ix | B14: ELECTRIFICATION AND ALLIED WORKS | C14: ELECTRIFICATION AND ALLIED WORKS | D14: Dismantling of existing wooden & aluminum partitions | E14: 10 | F14: 0 | G14: 0 | H14: 0 | I14: Sq.ft
A15: x | B15: ELECTRIFICATION AND ALLIED WORKS | C15: ELECTRIFICATION AND ALLIED WORKS | D15: Miscellaneous items such as false ceilings. | E15: 11 | F15: 0 | G15: 0 | H15: 0 | I15: Sq.ft
A16: xi | B16: ELECTRIFICATION AND ALLIED WORKS | C16: ELECTRIFICATION AND ALLIED WORKS | D16: Shifting /Dismantling existing furniture items (For renovation projects only) | E16: 487 | F16: 0 | G16: 0 | H16: 0 | I16: Nos.
A17: xii | B17: ELECTRIFICATION AND ALLIED WORKS | C17: ELECTRIFICATION AND ALLIED WORKS | D17: Dismantling of existing RCC 6 "/ 9" thk wall. | E17: 84 | F17: 2 | G17: 168 | H17: 0.07 | I17: Sq.ft
A18: 2 | B18: ELECTRIFICATION AND ALLIED WORKS | C18: ELECTRIFICATION AND ALLIED WORKS | D18: Construction of Masonry Walls | E18: 0 | F18: 0 | G18: 0 | H18: 0
A19: a | B19: ELECTRIFICATION AND ALLIED WORKS | C19: ELECTRIFICATION AND ALLIED WORKS | D19: Providing and erecting 115 mm thk , Half brick wall (first class bricks) in cement and sand mortar 1:3 with flush joint complete with material, labour, scaffolding, curing etc. The rate to include Appling chicken mesh at RCC to brickwork joints wherever required and RCC stiffener at every 1 meter intervals in 1:2:4 concrete. (Excluding plastering). The work to include cost for lintels / sills in RCC required for Doors , windows, openings etc. | E19: 114 | F19: 0 | G19: 0 | H19: 0 | I19: Sq.ft
A20: b | B20: ELECTRIFICATION AND ALLIED WORKS | C20: ELECTRIFICATION AND ALLIED WORKS | D20: Same as 2(a) but 230mm thk ( Single brick wall) | E20: 150 | F20: 0 | G20: 0 | H20: 0 | I20: Sq.ft
A21: c | B21: ELECTRIFICATION AND ALLIED WORKS | C21: ELECTRIFICATION AND ALLIED WORKS | D21: Do-do as 2(a) above but 100mm thk siporex / AAC / Aerocon / light weight block wall (Green Pro certified make approved by bank or CPC team as exception/ Refer make and model sheet,aerocon blocks) | E21: 124 | F21: 0 | G21: 0 | H21: 0 | I21: Sq.ft
A22: d | B22: ELECTRIFICATION AND ALLIED WORKS | C22: ELECTRIFICATION AND ALLIED WORKS | D22: Do-do as 2(a) above but 150mm thk siporex / AAC / Aerocon / light weight block wall (Green Pro certified make approved by bank or CPC team as exception/ Refer make and model sheet,aerocon blocks) | E22: 129 | F22: 851.4 | G22: 109830.6 | H22: 48.17 | I22: Sq.ft
A23: 3 | B23: ELECTRIFICATION AND ALLIED WORKS | C23: ELECTRIFICATION AND ALLIED WORKS | D23: R.C.C Works | E23: 0 | F23: 0 | G23: 0 | H23: 0
A24: a | B24: ELECTRIFICATION AND ALLIED WORKS | C24: ELECTRIFICATION AND ALLIED WORKS | D24: R.C.C work :Providing & casting in-situ reinforced cement concrete 225 mm thick for wall/columns/ as per details/ drawings/ design( The rate to include cost of re-baring/Hilti/drilling and joining with existing beam or lintel including shuttering, steel , concrete, inserts, cutout for ventilator, hacking, curing, bonding chemical / slurry all complete, design and certification from structural consultant. Grade of concrete to be considered shall be M25 & steel to be considered as 12mm dia tor steel @150mm c/c both way in two layers staggered by 75mm in both directions. The thickness of walls to be 225 mm without plaster. 300mm x300mm RCC column to be provided near the strong room door for mounting strong room door. | E24: 444 | F24: 0 | G24: 0 | H24: 0 | I24: Sq.ft
A25: b | B25: ELECTRIFICATION AND ALLIED WORKS | C25: ELECTRIFICATION AND ALLIED WORKS | D25: Do-do as 3(a) above but Ready mix concrete (Green Pro certified make approved by bank or CPC team as exception/ Refer make and model sheet,RMC) | E25: 699 | F25: 0 | G25: 0 | H25: 0 | I25: Sq.ft
A26: c | B26: ELECTRIFICATION AND ALLIED WORKS | C26: ELECTRIFICATION AND ALLIED WORKS | D26: Similar to above but for Floor slab with single layer of steel comprising 12mm dia @150 mm c/c and concrete jointing compound to be provided in case the premises is located on first floor and floor below does not belong to the bank. | E26: 198 | F26: 0 | G26: 0 | H26: 0 | I26: Sq.ft
A27: d | B27: ELECTRIFICATION AND ALLIED WORKS | C27: ELECTRIFICATION AND ALLIED WORKS | D27: Do-do as 3(c) above but Ready mix concrete (Green Pro certified make approved by bank or CPC team as exception/ Refer make and model sheet,RMC) | E27: 330 | F27: 0 | G27: 0 | H27: 0 | I27: Sq.ft
A28: e | B28: ELECTRIFICATION AND ALLIED WORKS | C28: ELECTRIFICATION AND ALLIED WORKS | D28: Similar to above but for Floor slab with double layer of steel comprising of 12 mm dia @ 150 mm c/c Mesh on both ways staggered by 75mm and concrete jointing compound to be provided in case the premises is located on first floor and floor below does not belong to the bank. | E28: 336 | F28: 0 | G28: 0 | H28: 0 | I28: Sq.ft
A29: f | B29: ELECTRIFICATION AND ALLIED WORKS | C29: ELECTRIFICATION AND ALLIED WORKS | D29: Do-do as 3(f) above but Ready mix concrete (Green Pro certified make approved by bank or CPC team as exception/ Refer make and model sheet,RMC) | E29: 453 | F29: 0 | G29: 0 | H29: 0 | I29: Sq.ft
A30: g | B30: ELECTRIFICATION AND ALLIED WORKS | C30: ELECTRIFICATION AND ALLIED WORKS | D30: Similar to above but without concrete (ceiling reinforcement Mesh to be provided in case upper floor does not belong to the bank) | E30: 129 | F30: 0 | G30: 0 | H30: 0 | I30: Sq.ft
A31: i | B31: ELECTRIFICATION AND ALLIED WORKS | C31: ELECTRIFICATION AND ALLIED WORKS | D31: Do-do as 3(g) above but Ready mix concrete (Green Pro certified make approved by bank or CPC team as exception/ Refer make and model sheet,RMC) | E31: 389 | F31: 0 | G31: 0 | H31: 0 | I31: Sq.ft
A32: j | B32: ELECTRIFICATION AND ALLIED WORKS | C32: ELECTRIFICATION AND ALLIED WORKS | D32: Similar to item 3(c) i.e. 6mm MS plate instead of reinforcement mesh for wall cladding. Including necessary MS framework. Complete as directed. | E32: 468 | F32: 0 | G32: 0 | H32: 0 | I32: Sq.ft
A33: k | B33: ELECTRIFICATION AND ALLIED WORKS | C33: ELECTRIFICATION AND ALLIED WORKS | D33: Fixing in place of Strong Room Door by providing necessary grouting in the floor and proper support. The vendor should ensure that the door is fixed in plumb. | E33: 8559 | F33: 0 | G33: 0 | H33: 0 | I33: Job
A34: l | B34: ELECTRIFICATION AND ALLIED WORKS | C34: ELECTRIFICATION AND ALLIED WORKS | D34: Fixing in place of Ventilator by providing necessary grouting in the floor and proper support. The vendor should ensure that the door is fixed in plumb. | E34: 5720 | F34: 0 | G34: 0 | H34: 0 | I34: Job
A35: 4 | B35: ELECTRIFICATION AND ALLIED WORKS | C35: ELECTRIFICATION AND ALLIED WORKS | D35: Plaster | E35: 0 | F35: 0 | G35: 0 | H35: 0
A36: a | B36: ELECTRIFICATION AND ALLIED WORKS | C36: ELECTRIFICATION AND ALLIED WORKS | D36: P/A 1:4 cement plaster(Green Pro certified make approved by bank or CPC team as exception/ Refer make and model sheet,cement) with waterproofing compound to brick/RCC work including scaffolding in single coat of minimum 12 mm thick finished to receive Plaster of Paris levelling coat. | E36: 46 | F36: 2317.13 | G36: 106587.98 | H36: 46.75 | I36: Sq.ft
A37: b | B37: ELECTRIFICATION AND ALLIED WORKS | C37: ELECTRIFICATION AND ALLIED WORKS | D37: External Plaster in 1:3 with waterproofing compound to brick/RCC work up to 25mm thk including cost of scaffolding up to 20'.( Prior approval of Bank required) (Green Pro certified make approved by bank or CPC team as exception/ Refer make and model sheet,cement) | E37: 62 | F37: 0 | G37: 0 | H37: 0 | I37: Sq.ft
A38: 5 | B38: ELECTRIFICATION AND ALLIED WORKS | C38: ELECTRIFICATION AND ALLIED WORKS | D38: Waterproofing treatment | E38: 0 | F38: 0 | G38: 0 | H38: 0
A39: a | B39: ELECTRIFICATION AND ALLIED WORKS | C39: ELECTRIFICATION AND ALLIED WORKS | D39: Providing & appling water proofing treatement by Mixing and applying two coats of ready-to-use acrylic polymer based waterproofing component on modified cement base of approved make to a thickness of 2 mm over the bottom and sides of toilet and pantry slabs, including preparation of surface, finishing, curing etc. all complete at all levels as per manufacturer's specifications and as directed. | E39: 45 | F39: 285.08 | G39: 12828.6 | H39: 5.63 | I39: Sq.ft
A40: 6 | B40: ELECTRIFICATION AND ALLIED WORKS | C40: ELECTRIFICATION AND ALLIED WORKS | D40: Brick Bat Coba | E40: 0 | F40: 0 | G40: 0 | H40: 0
...

Sheet Summary Sheet
A1: Sr. No | B1: Particulars | C1: Amount As per CWI | D1: Rate per sq.feet
A2: I | B2: POP & FALSE CEILING WORKS | C2: 1733162.6 | D2: 760
A3: II | B3: CARPENTRY AND INTERIOR WORKS | C3: 763801.48 | D3: 335
A4: III | B4: PAINTING WORKS | C4: 95319.01 | D4: 42
A5: IV | B5: ROLLING SHUTTER AND MS WORK | C5: 442709.8 | D5: 194
A6: V | B6: ELECTRIFICATION AND ALLIED WORKS | C6: 1576638.6 | D6: 692
A7: VI | B7: Additional Work | C7: 162810.6 | D7: 71
A8: Total | B8: Total | C8: 4774442.1 | D8: 2094

Sheet BOQ
C1: As per Work Order | G1: As per CWI | J1: Variance: CWI vs WO | L1: Excess | M1: Savings | N1: Total | O1: Remarks
A2: Sr. No | B2: Particulars | C2: Qty | D2: Unit | E2: Rate | F2: Amount | G2: Qty | H2: Round off | I2: Amount | J2: Qty. | K2: Amount | L2: Amount | M2: Amount | N2: Amount | O2: Remarks
A3: I | B3: CIVIL & RELATED WORKS
A4: 1 | B4: Demolition / Clearing Works
A5: a | B5: Dismantling/Demolishing the following and carting away the debris from the site and unloading at a approved location as per statutory rules and regulations.
A6: i | B6: Dismantling of existing brickwork | D6: Sq.ft | E6: 12 | F6: =E6*C6 -> 0 | H6: =ROUND(G6,2) -> 0 | I6: =H6*E6 -> 0 | J6: =G6-C6 -> 0 | K6: =I6-F6 -> 0 | L6: =IF(F6<I6,(I6-F6),0) -> 0 | M6: =IF(F6>I6,(I6-F6),0) -> 0 | N6: =M6+L6 -> 0
A7: ii | B7: Dismantling of existing dado tiles without plaster | D7: Sq.ft | E7: 11 | F7: =E7*C7 -> 0 | G7: ='Measurement sheet'!F26 -> 932.39 | H7: =ROUND(G7,2) -> 932.39 | I7: =H7*E7 -> 10256.29 | J7: =G7-C7 -> 932.39 | K7: =I7-F7 -> 10256.29 | L7: =IF(F7<I7,(I7-F7),0) -> 10256.29 | M7: =IF(F7>I7,(I7-F7),0) -> 0 | N7: =M7+L7 -> 10256.29 | O7: Quantity measured on best effort basis from photographs and layouts. PM confirmation required for whether items were executed on site and Qty not Present in WO.
A8: iii | B8: Dismantling of existing plaster | D8: Sq.ft | E8: 11 | F8: =E8*C8 -> 0 | G8: ='Measurement sheet'!F35 -> 459.7317 | H8: =ROUND(G8,2) -> 459.73 | I8: =H8*E8 -> 5057.03 | J8: =G8-C8 -> 459.7317 | K8: =I8-F8 -> 5057.03 | L8: =IF(F8<I8,(I8-F8),0) -> 5057.03 | M8: =IF(F8>I8,(I8-F8),0) -> 0 | N8: =M8+L8 -> 5057.03 | O8: Quantity measured on best effort basis from photographs and layouts. PM confirmation required for whether items were executed on site and Qty not Present in WO.
A9: iv | B9: Existing flooring including bedding material & PCC/IPS. | D9: Sq.ft | E9: 16 | F9: =E9*C9 -> 0 | G9: ='Measurement sheet'!F47 -> 540.8335 | H9: =ROUND(G9,2) -> 540.83 | I9: =H9*E9 -> 8653.28 | J9: =G9-C9 -> 540.8335 | K9: =I9-F9 -> 8653.28 | L9: =IF(F9<I9,(I9-F9),0) -> 8653.28 | M9: =IF(F9>I9,(I9-F9),0) -> 0 | N9: =M9+L9 -> 8653.28 | O9: Quantity measured on best effort basis from photographs and layouts. PM confirmation required for whether items were executed on site and Qty not Present in WO.
A10: v | B10: Existing Doors / Windows | D10: Nos. | E10: 381 | F10: =E10*C10 -> 0 | G10: ='Measurement sheet'!F51 -> 16 | H10: =ROUND(G10,2) -> 16 | I10: =H10*E10 -> 6096 | J10: =G10-C10 -> 16 | K10: =I10-F10 -> 6096 | L10: =IF(F10<I10,(I10-F10),0) -> 6096 | M10: =IF(F10>I10,(I10-F10),0) -> 0 | N10: =M10+L10 -> 6096 | O10: Quantity measured on best effort basis from photographs and layouts. PM confirmation required for whether items were executed on site and Qty not Present in WO.
A11: vi | B11: Dismantling of existing Sanitary wares & Plumbing Fittings | D11: Nos. | E11: 1199 | F11: =E11*C11 -> 0 | H11: =ROUND(G11,2) -> 0 | I11: =H11*E11 -> 0 | J11: =G11-C11 -> 0 | K11: =I11-F11 -> 0 | L11: =IF(F11<I11,(I11-F11),0) -> 0 | M11: =IF(F11>I11,(I11-F11),0) -> 0 | N11: =M11+L11 -> 0
A12: vii | B12: Existing Rolling Shutter , Safety door, collapsible door etc. | D12: Sq.ft | E12: 11 | F12: =E12*C12 -> 0 | H12: =ROUND(G12,2) -> 0 | I12: =H12*E12 -> 0 | J12: =G12-C12 -> 0 | K12: =I12-F12 -> 0 | L12: =IF(F12<I12,(I12-F12),0) -> 0 | M12: =IF(F12>I12,(I12-F12),0) -> 0 | N12: =M12+L12 -> 0
A13: viii | B13: Existing Electrical fittings and fixtures | D13: Sq.ft | E13: 3 | F13: =E13*C13 -> 0 | H13: =ROUND(G13,2) -> 0 | I13: =H13*E13 -> 0 | J13: =G13-C13 -> 0 | K13: =I13-F13 -> 0 | L13: =IF(F13<I13,(I13-F13),0) -> 0 | M13: =IF(F13>I13,(I13-F13),0) -> 0 | N13: =M13+L13 -> 0
A14: ix | B14: Dismantling of existing wooden & aluminum partitions | D14: Sq.ft | E14: 10 | F14: =E14*C14 -> 0 | H14: =ROUND(G14,2) -> 0 | I14: =H14*E14 -> 0 | J14: =G14-C14 -> 0 | K14: =I14-F14 -> 0 | L14: =IF(F14<I14,(I14-F14),0) -> 0 | M14: =IF(F14>I14,(I14-F14),0) -> 0 | N14: =M14+L14 -> 0
A15: x | B15: Miscellaneous items such as false ceilings. | D15: Sq.ft | E15: 11 | F15: =E15*C15 -> 0 | H15: =ROUND(G15,2) -> 0 | I15: =H15*E15 -> 0 | J15: =G15-C15 -> 0 | K15: =I15-F15 -> 0 | L15: =IF(F15<I15,(I15-F15),0) -> 0 | M15: =IF(F15>I15,(I15-F15),0) -> 0 | N15: =M15+L15 -> 0
A16: xi | B16: Shifting /Dismantling existing furniture items (For renovation projects only) | D16: Nos. | E16: 487 | F16: =E16*C16 -> 0 | H16: =ROUND(G16,2) -> 0 | I16: =H16*E16 -> 0 | J16: =G16-C16 -> 0 | K16: =I16-F16 -> 0 | L16: =IF(F16<I16,(I16-F16),0) -> 0 | M16: =IF(F16>I16,(I16-F16),0) -> 0 | N16: =M16+L16 -> 0
A17: xii | B17: Dismantling of existing RCC 6 "/ 9" thk wall. | D17: Sq.ft | E17: 84 | F17: =E17*C17 -> 0 | G17: ='Measurement sheet'!F54 -> 2 | H17: =ROUND(G17,2) -> 2 | I17: =H17*E17 -> 168 | J17: =G17-C17 -> 2 | K17: =I17-F17 -> 168 | L17: =IF(F17<I17,(I17-F17),0) -> 168 | M17: =IF(F17>I17,(I17-F17),0) -> 0 | N17: =M17+L17 -> 168 | O17: Quantity measured on best effort basis from photographs and layouts. PM confirmation required for whether items were executed on site and Qty not Present in WO.
A19: 2 | B19: Construction of Masonry Walls
A20: a | B20: Providing and erecting 115 mm thk , Half brick wall (first class bricks) in cement and sand mortar 1:3 with flush joint complete with material, labour, scaffolding, curing etc. The rate to include Appling chicken mesh at RCC to brickwork joints wherever required and RCC stiffener at every 1 meter intervals in 1:2:4 concrete. (Excluding plastering). The work to include cost for lintels / sills in RCC required for Doors , windows, openings etc. | D20: Sq.ft | E20: 114 | F20: =E20*C20 -> 0 | H20: =ROUND(G20,2) -> 0 | I20: =H20*E20 -> 0 | J20: =G20-C20 -> 0 | K20: =I20-F20 -> 0 | L20: =IF(F20<I20,(I20-F20),0) -> 0 | M20: =IF(F20>I20,(I20-F20),0) -> 0 | N20: =M20+L20 -> 0
A21: b | B21: Same as 2(a) but 230mm thk ( Single brick wall) | D21: Sq.ft | E21: 150 | F21: =E21*C21 -> 0 | H21: =ROUND(G21,2) -> 0 | I21: =H21*E21 -> 0 | J21: =G21-C21 -> 0 | K21: =I21-F21 -> 0 | L21: =IF(F21<I21,(I21-F21),0) -> 0 | M21: =IF(F21>I21,(I21-F21),0) -> 0 | N21: =M21+L21 -> 0
A22: c | B22: Do-do as 2(a) above but 100mm thk siporex / AAC / Aerocon / light weight block wall (Green Pro certified make approved by bank or CPC team as exception/ Refer make and model sheet,aerocon blocks) | D22: Sq.ft | E22: 124 | F22: =E22*C22 -> 0 | H22: =ROUND(G22,2) -> 0 | I22: =H22*E22 -> 0 | J22: =G22-C22 -> 0 | K22: =I22-F22 -> 0 | L22: =IF(F22<I22,(I22-F22),0) -> 0 | M22: =IF(F22>I22,(I22-F22),0) -> 0 | N22: =M22+L22 -> 0
A23: d | B23: Do-do as 2(a) above but 150mm thk siporex / AAC / Aerocon / light weight block wall (Green Pro certified make approved by bank or CPC team as exception/ Refer make and model sheet,aerocon blocks) | C23: 850 | D23: Sq.ft | E23: 129 | F23: =E23*C23 -> 109650 | G23: ='Measurement sheet'!F80 -> 851.395 | H23: =ROUND(G23,2) -> 851.4 | I23: =H23*E23 -> 109830.6 | J23: =G23-C23 -> 1.395 | K23: =I23-F23 -> 180.6 | L23: =IF(F23<I23,(I23-F23),0) -> 180.6 | M23: =IF(F23>I23,(I23-F23),0) -> 0 | N23: =M23+L23 -> 180.6 | O23: Quantiy has exceeded WO Quantity, PM Approval is required for excess quantity
A25: 3 | B25: R.C.C Works
A26: a | B26: R.C.C work :Providing & casting in-situ reinforced cement concrete 225 mm thick for wall/columns/ as per details/ drawings/ design( The rate to include cost of re-baring/Hilti/drilling and joining with existing beam or lintel including shuttering, steel , concrete, inserts, cutout for ventilator, hacking, curing, bonding chemical / slurry all complete, design and certification from structural consultant. Grade of concrete to be considered shall be M25 & steel to be considered as 12mm dia tor steel @150mm c/c both way in two layers staggered by 75mm in both directions. The thickness of walls to be 225 mm without plaster. 300mm x300mm RCC column to be provided near the strong room door for mounting strong room door. | D26: Sq.ft | E26: 444 | F26: =E26*C26 -> 0 | H26: =ROUND(G26,2) -> 0 | I26: =H26*E26 -> 0 | J26: =G26-C26 -> 0 | K26: =I26-F26 -> 0 | L26: =IF(F26<I26,(I26-F26),0) -> 0 | M26: =IF(F26>I26,(I26-F26),0) -> 0 | N26: =M26+L26 -> 0
A27: b | B27: Do-do as 3(a) above but Ready mix concrete (Green Pro certified make approved by bank or CPC team as exception/ Refer make and model sheet,RMC) | D27: Sq.ft | E27: 699 | F27: =E27*C27 -> 0 | H27: =ROUND(G27,2) -> 0 | I27: =H27*E27 -> 0 | J27: =G27-C27 -> 0 | K27: =I27-F27 -> 0 | L27: =IF(F27<I27,(I27-F27),0) -> 0 | M27: =IF(F27>I27,(I27-F27),0) -> 0 | N27: =M27+L27 -> 0
A28: c | B28: Similar to above but for Floor slab with single layer of steel comprising 12mm dia @150 mm c/c and concrete jointing compound to be provided in case the premises is located on first floor and floor below does not belong to the bank. | D28: Sq.ft | E28: 198 | F28: =E28*C28 -> 0 | H28: =ROUND(G28,2) -> 0 | I28: =H28*E28 -> 0 | J28: =G28-C28 -> 0 | K28: =I28-F28 -> 0 | L28: =IF(F28<I28,(I28-F28),0) -> 0 | M28: =IF(F28>I28,(I28-F28),0) -> 0 | N28: =M28+L28 -> 0
A29: d | B29: Do-do as 3(c) above but Ready mix concrete (Green Pro certified make approved by bank or CPC team as exception/ Refer make and model sheet,RMC) | D29: Sq.ft | E29: 330 | F29: =E29*C29 -> 0 | H29: =ROUND(G29,2) -> 0 | I29: =H29*E29 -> 0 | J29: =G29-C29 -> 0 | K29: =I29-F29 -> 0 | L29: =IF(F29<I29,(I29-F29),0) -> 0 | M29: =IF(F29>I29,(I29-F29),0) -> 0 | N29: =M29+L29 -> 0
A30: e | B30: Similar to above but for Floor slab with double layer of steel comprising of 12 mm dia @ 150 mm c/c Mesh on both ways staggered by 75mm and concrete jointing compound to be provided in case the premises is located on first floor and floor below does not belong to the bank. | D30: Sq.ft | E30: 336 | F30: =E30*C30 -> 0 | H30: =ROUND(G30,2) -> 0 | I30: =H30*E30 -> 0 | J30: =G30-C30 -> 0 | K30: =I30-F30 -> 0 | L30: =IF(F30<I30,(I30-F30),0) -> 0 | M30: =IF(F30>I30,(I30-F30),0) -> 0 | N30: =M30+L30 -> 0
A31: f | B31: Do-do as 3(f) above but Ready mix concrete (Green Pro certified make approved by bank or CPC team as exception/ Refer make and model sheet,RMC) | D31: Sq.ft | E31: 453 | F31: =E31*C31 -> 0 | H31: =ROUND(G31,2) -> 0 | I31: =H31*E31 -> 0 | J31: =G31-C31 -> 0 | K31: =I31-F31 -> 0 | L31: =IF(F31<I31,(I31-F31),0) -> 0 | M31: =IF(F31>I31,(I31-F31),0) -> 0 | N31: =M31+L31 -> 0
A32: g | B32: Similar to above but without concrete (ceiling reinforcement Mesh to be provided in case upper floor does not belong to the bank) | D32: Sq.ft | E32: 129 | F32: =E32*C32 -> 0 | H32: =ROUND(G32,2) -> 0 | I32: =H32*E32 -> 0 | J32: =G32-C32 -> 0 | K32: =I32-F32 -> 0 | L32: =IF(F32<I32,(I32-F32),0) -> 0 | M32: =IF(F32>I32,(I32-F32),0) -> 0 | N32: =M32+L32 -> 0
A33: i | B33: Do-do as 3(g) above but Ready mix concrete (Green Pro certified make approved by bank or CPC team as exception/ Refer make and model sheet,RMC) | D33: Sq.ft | E33: 389 | F33: =E33*C33 -> 0 | H33: =ROUND(G33,2) -> 0 | I33: =H33*E33 -> 0 | J33: =G33-C33 -> 0 | K33: =I33-F33 -> 0 | L33: =IF(F33<I33,(I33-F33),0) -> 0 | M33: =IF(F33>I33,(I33-F33),0) -> 0 | N33: =M33+L33 -> 0
A34: j | B34: Similar to item 3(c) i.e. 6mm MS plate instead of reinforcement mesh for wall cladding. Including necessary MS framework. Complete as directed. | D34: Sq.ft | E34: 468 | F34: =E34*C34 -> 0 | H34: =ROUND(G34,2) -> 0 | I34: =H34*E34 -> 0 | J34: =G34-C34 -> 0 | K34: =I34-F34 -> 0 | L34: =IF(F34<I34,(I34-F34),0) -> 0 | M34: =IF(F34>I34,(I34-F34),0) -> 0 | N34: =M34+L34 -> 0
A35: k | B35: Fixing in place of Strong Room Door by providing necessary grouting in the floor and proper support. The vendor should ensure that the door is fixed in plumb. | D35: Job | E35: 8559 | F35: =E35*C35 -> 0 | H35: =ROUND(G35,2) -> 0 | I35: =H35*E35 -> 0 | J35: =G35-C35 -> 0 | K35: =I35-F35 -> 0 | L35: =IF(F35<I35,(I35-F35),0) -> 0 | M35: =IF(F35>I35,(I35-F35),0) -> 0 | N35: =M35+L35 -> 0
A36: l | B36: Fixing in place of Ventilator by providing necessary grouting in the floor and proper support. The vendor should ensure that the door is fixed in plumb. | D36: Job | E36: 5720 | F36: =E36*C36 -> 0 | H36: =ROUND(G36,2) -> 0 | I36: =H36*E36 -> 0 | J36: =G36-C36 -> 0 | K36: =I36-F36 -> 0 | L36: =IF(F36<I36,(I36-F36),0) -> 0 | M36: =IF(F36>I36,(I36-F36),0) -> 0 | N36: =M36+L36 -> 0
A38: 4 | B38: Plaster
A39: a | B39: P/A 1:4 cement plaster(Green Pro certified make approved by bank or CPC team as exception/ Refer make and model sheet,cement) with waterproofing compound to brick/RCC work including scaffolding in single coat of minimum 12 mm thick finished to receive Plaster of Paris levelling coat. | C39: 2320 | D39: Sq.ft | E39: 46 | F39: =E39*C39 -> 106720 | G39: ='Measurement sheet'!F100 -> 2317.1297 | H39: =ROUND(G39,2) -> 2317.13 | I39: =H39*E39 -> 106587.98 | J39: =G39-C39 -> -2.8703 | K39: =I39-F39 -> -132.02 | L39: =IF(F39<I39,(I39-F39),0) -> 0 | M39: =IF(F39>I39,(I39-F39),0) -> -132.02 | N39: =M39+L39 -> -132.02
A40: b | B40: External Plaster in 1:3 with waterproofing compound to brick/RCC work up to 25mm thk including cost of scaffolding up to 20'.( Prior approval of Bank required) (Green Pro certified make approved by bank or CPC team as exception/ Refer make and model sheet,cement) | D40: Sq.ft | E40: 62 | F40: =E40*C40 -> 0 | H40: =ROUND(G40,2) -> 0 | I40: =H40*E40 -> 0 | J40: =G40-C40 -> 0 | K40: =I40-F40 -> 0 | L40: =IF(F40<I40,(I40-F40),0) -> 0 | M40: =IF(F40>I40,(I40-F40),0) -> 0 | N40: =M40+L40 -> 0
A42: 5 | B42: Waterproofing treatment
A43: a | B43: Providing & appling water proofing treatement by Mixing and applying two coats of ready-to-use acrylic polymer based waterproofing component on modified cement base of approved make to a thickness of 2 mm over the bottom and sides of toilet and pantry slabs, including preparation of surface, finishing, curing etc. all complete at all levels as per manufacturer's specifications and as directed. | C43: 380 | D43: Sq.ft | E43: 45 | F43: =E43*C43 -> 17100 | G43: ='Measurement sheet'!F113 -> 285.0835 | H43: =ROUND(G43,2) -> 285.08 | I43: =H43*E43 -> 12828.6 | J43: =G43-C43 -> -94.9165 | K43: =I43-F43 -> -4271.4 | L43: =IF(F43<I43,(I43-F43),0) -> 0 | M43: =IF(F43>I43,(I43-F43),0) -> -4271.4 | N43: =M43+L43 -> -4271.4
A45: 6 | B45: Brick Bat Coba
...

Sheet Measurement sheet
A1: HDFC BANK ICHALKARANJI (SECOND FLOOR) - MEASUREMENT SHEET
A2: Sr. No. | B2: PARTICULARS | C2: NO | D2: L | E2: B/D | F2: QTY | G2: Remark
A3: I | B3: CIVIL & RELATED WORKS
A4: 1 | B4: Demolition / Clearing Works
A5: ii | B5: Dismantling of existing dado tiles without plaster
B6: Hub Room Old Tiles | C6: 1 | D6: 10.52 | E6: 9 | F6: =C6*D6*E6 -> 94.68
C7: 1 | D7: 6.97 | E7: 9 | F7: =C7*D7*E7 -> 62.73
B8: Gents Washroom | C8: 1 | D8: 16.17 | E8: 9 | F8: =C8*D8*E8 -> 145.53
B9: Pantry | C9: 1 | D9: 12 | E9: 9 | F9: =C9*D9*E9 -> 108
B10: Conference Room | C10: 1 | D10: 18.33 | E10: 9 | F10: =C10*D10*E10 -> 164.97
B11: CH Cabin Wall | C11: 1 | D11: 5.36 | E11: 9 | F11: =C11*D11*E11 -> 48.24
B12: RM Wall | C12: 1 | D12: 5.36 | E12: 9 | F12: =C12*D12*E12 -> 48.24
B13: RM near Window | C13: 1 | D13: 8 | E13: 3 | F13: =C13*D13*E13 -> 24
B14: RM Area Column 1 & 2 | C14: 2 | D14: 3.5 | E14: 9 | F14: =C14*D14*E14 -> 63
B15: RM Area Cloumn 3, 4 & 5 | C15: 3 | D15: 2 | E15: 9 | F15: =C15*D15*E15 -> 54 | G15: Photos and CAD File with marking
B16: Server Window Granite 7 x 3 | C16: 1 | D16: 20 | E16: 0.5 | F16: =C16*D16*E16 -> 10
B17: Store Window Granite 4 x 3 | C17: 1 | D17: 48 | E17: 0.5 | F17: =C17*D17*E17 -> 24
B18: Store Door Frame 7 x 3 | C18: 1 | D18: 20 | E18: 0.5 | F18: =C18*D18*E18 -> 10
B19: Ladies Window Granite 5.5 x 4 | C19: 1 | D19: 19 | E19: 0.5 | F19: =C19*D19*E19 -> 9.5
B20: Gents Window Granite 2 x 3 | C20: 1 | D20: 10 | E20: 0.5 | F20: =C20*D20*E20 -> 5
B21: Gents Window Granite 4 x 4 | C21: 1 | D21: 16 | E21: 0.5 | F21: =C21*D21*E21 -> 8
B22: Pantry Window Granite 4 x 4 - 2nos / 5.5 x 4 / 2 x 3 | C22: 1 | D22: 45 | E22: 0.5 | F22: =C22*D22*E22 -> 22.5
B23: Conf Window Granite 2 x 3 - 4nos | C23: 1 | D23: 40 | E23: 0.5 | F23: =C23*D23*E23 -> 20
B24: CH Window Granite 2 x 3 | C24: 1 | D24: 10 | E24: 0.5 | F24: =C24*D24*E24 -> 5
B25: RM Window Granite 2 x 3 | C25: 1 | D25: 10 | E25: 0.5 | F25: =C25*D25*E25 -> 5
C26: TOTAL | F26: =SUM(F6:F25) -> 932.39
A27: iii | B27: Dismantling of existing plaster
B28: Store Room | C28: 1 | D28: 8.95 | E28: 9 | F28: =C28*D28*E28 -> 80.55
B29: Deduction - Door | C29: -1 | D29: 3 | E29: 6.82 | F29: =C29*D29*E29 -> -20.46
B30: Ladies Washroom | C30: 1 | D30: 5.36 | E30: 9 | F30: =C30*D30*E30 -> 48.24 | G30: Photos and CAD FILE with marking
B31: Pantry | C31: 1 | D31: 10.78 | E31: 9 | F31: =C31*D31*E31 -> 97.02
B32: Deduction - Window | C32: -1 | D32: 5.79 | E32: 3.77 | F32: =C32*D32*E32 -> -21.8283
B33: Hub Entry Column | C33: 1 | D33: 2 | E33: 9 | F33: =C33*D33*E33 -> 18
B34: Graphic Wall | C34: 1 | D34: 28.69 | E34: 9 | F34: =C34*D34*E34 -> 258.21
C35: TOTAL | F35: =SUM(F28:F34) -> 459.7317
A36: iv | B36: Existing flooring including bedding material & PCC/IPS.
B37: Hub Room | C37: 1 | D37: 12 | E37: 2 | F37: =C37*D37*E37 -> 24
B38: Ladies Washroom | C38: 1 | D38: 7.93 | E38: 5.45 | F38: =C38*D38*E38 -> 43.2185
B39: Deduction - Column | C39: -1 | D39: 1.54 | E39: 2.5 | F39: =C39*D39*E39 -> -3.85
B40: Gents Washroom | C40: 1 | D40: 10.42 | E40: 5.75 | F40: =C40*D40*E40 -> 59.915
...

Sheet Debit
A1: U.Code | B1: Sr.No | C1: Particulars | D1: Unit | E1: Rate | F1: Earlier Qty | G1: Eariler Amount | H1: Revised Qty as per CWI | I1: Final Amount | J1: Remarks
C3: Civil & related works
A4: i | B4: i | C4: Providing and fixing in place, branch manager's table of size 1575mm x 675mm(worktop size)comprising of 25mm thick table top made of medium density particle board with side credenza of size 400mm deep and 900mm long having sliding shutters with locks ( Make : Ebco ) and a 3 drawer pedestal of size 400mm x 500 mm x700mm consisting of 2nos. drawer of 150mm deep and 300mm deep filing drawer having common lock ( Make : Ebco ) including modesty apron to be made out of 19mm thick BWR plywood (use Plywood which are "Free of Added Urea Formaldehyde" (required) and Green Pro certified (Mandatory) and make approved by Bank or CPC team as exception / Refer Make and Model sheet, BWR Plywood) /high Density particle board. The table top to have post form edge. All complete including key board drawer, M.S. Powder coated Cable tray to place electrical sockets on it, CPU trolley and necessary hardware .( Make : Ebco) all the external surfaces to be finished with 1.0mm thick laminate and internal surfaces to be finished with 0.8 mm thick laminate of approved shade. all complete as directed.( All furniture hardware should be Ebco Make ) | D4: Nos | E4: 28249 | F4: 2 | G4: =F4*E4 -> 56498 | H4: =F4-0.25 -> 1.75 | I4: =H4*E4 -> 49435.75 | J4: A 25% debit has been imposed due to the non-provision of the keyboard tray and 3-drawer pedestal as per the approved specifications and the quantity has been rounded off accordingly
A5: III_5.b.iii | B5: iii | C5: same as item 5(a) above but size of the worktable to be 1200mm x 675mm with drawer pedestal and without side credenza. | E5: 20488 | F5: 8 | G5: =F5*E5 -> 163904 | H5: 7.65 | I5: =H5*E5 -> 156733.2 | J5: A debit of ₹900 has been imposed due to the non-provision of the keyboard tray as per the approved specifications, and the quantity has been rounded off accordingly
A6: III_5.d.i | B6: i | C6: Providing and fixing in place 600mm deep running counter made of medium density particle board with post form edge profile for 25mm thick table top, Consisting of a 3 drawer pedestal of size 400mm x 500 mm x700mm consisting of 2nos. drawer of 150mm deep and 300mm deep filing drawer having common lock ( Make : Ebco ) including modesty apron to be made out of 19mm thick BWR plywood (use Plywood which are "Free of Added Urea Formaldehyde" (required) and Green Pro certified (Mandatory) and make approved by Bank or CPC team as exception / Refer Make and Model sheet, BWR Plywood) /high particle board. All complete including key board drawer, M.S. Powder coated Cable tray to place electrical sockets on it, CPU trolley and necessary hardware.All the exposed surfaces to be finished with 1.0mm thick laminate.( All furniture hardware should be Ebco Make ) | E6: 16568 | F6: 2 | G6: =F6*E6 -> 33136 | H6: 1.89 | I6: =H6*E6 -> 31313.52 | J6: A debit of ₹900 has been imposed due to the non-provision of the keyboard tray as per the approved specifications, and the quantity has been rounded off accordingly
A7: III_5.e.i | B7: i | C7: Providing and fixing welcome desk consisting of two worktops (laminate and glass/granite) with a cabinet to house FRFC made of 19mm thick BWR plywood top, sides finished in 1.0mm thick laminate of approved shade. The table shall have a 3 drawer pedestal of size 400mm x 500 mm x700mm consisting of 2nos. drawer of 150mm deep and 300mm deep filing drawer having common lock ( Make : Ebco ) including modesty apron to be made out of 19mm thick BWR plywood (use Plywood which are "Free of Added Urea Formaldehyde" (required) and Green Pro certified (Mandatory) and make approved by Bank or CPC team as exception / Refer Make and Model sheet, BWR Plywood) /high particle board. with key boards and CPU stand complete with all hardware etc. all the exposed edges to have wooden lipping stained to match the laminate and Melaminee finished. all the internal surfaces to be hand Melamine Polished. ( All furniture hardware should be Ebco Make ) | E7: 24336 | F7: 1 | G7: =F7*E7 -> 24336 | H7: 0.96 | I7: =H7*E7 -> 23362.56 | J7: A debit of ₹900 has been imposed due to the non-provision of the keyboard tray as per the approved specifications, and the quantity has been rounded off accordingly
A8: III_5.f.i | B8: i | C8: P/f Double level teller counter made out of 19mm thick plywood (use Plywood which are "Free of Added Urea Formaldehyde" (required) and Green Pro certified (Mandatory) and make approved by Bank or CPC team as exception / Refer Make and Model sheet, BWR Plywood) and finished in laminate one at 750mm and other at 1200mm level. Top level counter to be finished in jet black granite with double molding. The upper most worktop to have vertical barriers in form of 8 mm thick toughen glass mounted on ss finish fabricated brackets for cash transactions. Teller to be provided with 4 nos. equal sized drawers, one key board at every 1200mm length. There should be a vertical barrier separating the adjacent counter at every 1200mm length. All the exposed surfaces to be finished with 1.0mm thick laminate and internal surfaces to be finished with hand Melamine Polish. all 5 S compliances as per bank's requirements to be followed. ( All furniture hardware should be Ebco Make ) | D8: R.ft | E8: 3813 | F8: 4.44 | G8: =F8*E8 -> 16929.72 | H8: 4.2 | I8: =H8*E8 -> 16014.6 | J8: A debit of ₹900 has been imposed due to the non-provision of the keyboard tray as per the approved specifications, and the quantity has been rounded off accordingly
C12: ELECTRIFICATION AND ALLIED WORKS
A13: VI_1.1.2 | B13: 1.1.2 | C13: TYPE I PANEL - Main LT Panel (For 1500-2500 sq. ft) | D13: Nos | E13: 155313 | F13: 1 | G13: =F13*E13 -> 155313 | H13: =F13-0.065 -> 0.935 | I13: =H13*E13 -> 145217.65 | J13: A 6% debit has been imposed due to the non-provision of 1 No. 32A TPN MCB and 1 No. 80A TP MCCB (Incomer) as per the approved specification.

Sheet Documnets
A1: Sr. No | B1: Description | C1: Unit | D1: Qty Claimed | E1: Photos and Documents Requird
A2: Demolition / Clearing Works
A3: 1 | B3: Dismantling of existing dado tiles without plaster | C3: Sq.ft | D3: 932.39 | E3: Photos required & Existing Layout with Marking and CAD File
A4: 2 | B4: Dismantling of existing plaster | C4: Sq.ft | D4: 459.73 | E4: Photos required & Existing Layout with Marking and CAD File
A5: 3 | B5: Existing flooring including bedding material & PCC/IPS. | C5: Sq.ft | D5: 540.83 | E5: Photos required
A6: 4 | B6: Windows and Door | C6: Nos | D6: 16 | E6: Photos required & Existing Layout
A7: 5 | B7: Dismantling of existing RCC 6 "/ 9" thk wall. | C7: Sq.ft | D7: 2 | E7: Photos required
A8: 6 | B8: Construction of Masonry Walls
B9: Hub Room Window | C9: Sq.ft | D9: 21 | E9: Photos required
B10: Ladies Window | C10: Sq.ft | D10: 22
B11: Gents Window | C11: Sq.ft | D11: 8
B12: Pantry Window | C12: Sq.ft | D12: 6
B13: Conf Window | C13: Sq.ft | D13: 24
B14: CH Windpw | C14: Sq.ft | D14: 6
B15: RM Window | C15: Sq.ft | D15: 6
A16: 7 | B16: Plaster
B17: CH Cabin | C17: Sq.ft | D17: 58.5
B18: RM Area | C18: Sq.ft | D18: 58.5
B19: RM Arear near Window | C19: Sq.ft | D19: 15
A20: 8 | B20: Waterproofing Photos | C20: Sq.ft | D20: 285.08 | E20: Photos required
A21: 9 | B21: Brickbat work | C21: Sq.ft | D21: 109.28 | E21: Photos required
A22: 10 | B22: PCC Work | C22: Sq.ft | D22: 534.5 | E22: Photos required
A23: 11 | B23: POP covering on Flooring | C23: Sq.ft | D23: 2191.5 | E23: Photos required Staircase Area As well
A24: 12 | B24: Trenching work as per width and depth required. | C24: R.ft | D24: 190 | E24: Photos required
A25: 13 | B25: Making punctures in existing brick/siporex block up to 200mm diameter, | C25: Nos | D25: 1 | E25: Photos required
A26: 14 | B26: MS H Type Frame | C26: Sq.ft | D26: 350 | E26: Photos required
A27: 15 | B27: C02 Monitoring | C27: Nos | D27: 3 | E27: Pending
A28: 16 | B28: POP Punning - Graphic Wall | C28: Sq.ft | D28: 49.76 | E28: Photos required
A29: 17 | B29: 600mm x 600mm Modular Grid Ceiling : Around AC in Pantry | E29: Photos required
A30: 18 | B30: Washroom Antilobby Door Glass fixed Photos | C30: Nos | D30: 1 | E30: Photos required
A31: 19 | B31: For 3 Phase UPS 40 Amp MCB to 63 AMP MCB Change | C31: Nos | D31: 1 | E31: Geo Tag Photos required
A32: 20 | B32: TPN, 8 Way (above 2500 Sq. ft area) 40 Amp MCB to 63 AMP MCB Change | C32: Nos | D32: 1 | E32: Geo Tag Photos required
A33: 21 | B33: TPN, 8 Way (above 2500 Sq. ft area) -40 Amp MCB to 63 AMP MCB Change | C33: Nos | D33: 1 | E33: Geo Tag Photos required
A34: 22 | B34: 6 amps Light Plug Outlets :- Conference Room | C34: Nos | D34: 4 | E34: Geo Tag Photos required
A35: 23 | B35: Wooden Fire Rated Door | E35: Certficate Required
A36: 24 | B36: All Inovices (Including Painting Plumbing, Eletrical,Carpentry, Waterproofing, Cement, Blockwork, Tuffen glass, Modular) | E36: As mentioned, all required invoices
A37: 25 | B37: Glazed Glass Invoice
A38: 26 | B38: Frosted Film
A39: 27 | B39: IGBC | E39: Required Product Certficate that has been used in the branch
A40: 28 | B40: CAR and WC | E40: Policies

Sheet Make and Models
A1: LIST OF MATERIALS & APPROVED BRANDS FOR HDFC Bank
B2: Material | C2: IMP Criteria | D2: Approved brands
B3: Civil Items
A4: 1 | B4: Cement | C4: Green Pro Certification | D4: ACC 1. ACC Suraksha Power 2. ACC Gold Water Shield 3. ACC F2R Superfast 4. ACC HPC Long Life 5. ACC Concrete+ Xtra Strong JK Lakshmi Cement Ltd 1. COC 2. PPC 3. Sixer 4. HDP 5. PHDP 6. Platinum 7. PSC 8. PRO Plus UltraTech Cement Limited 1. UltraTech Premium, Composite Cement 2. UltraTech Weather Plus, Composite Cement 3. UltraTech Weather Plus, Portland Pozzolana Cement 4. UltraTech, Composite Cement 5. UltraTech, Portland Pozzolana Cement Dalmia Cement 1. Vajram Cement - Portland Pozzolana Cement (PPC) JSW Cement Ltd 1. portland Slag Cement 2. Composite Cement
A5: 2 | B5: Ready Mixed Concrete | C5: Green Pro Certification | D5: ACC : ACC ECOPACT ACC Feathercrete ACC Fillcrete ACC Flowcrete ACC Permicrete ULTRATECH : Ultratech Duracon Ultratech Flowfill Ultratech Free flow Ultratech Hypercon
A6: 3 | B6: Aerocon Block | C6: Green Pro Certification | D6: Ultra Tech 1. Extralite- AAC Blocks JK Lakshmi Cement Ltd 1.JK Smartblox Godrej 1. Tuff Blocks JVS Comatsco Industries Pvt. Ltd 1. Ecolite AAC Blocks KD Infra 1.Brikolite AAC Block UAL Industries Ltd 1.KON_CRETE AAC blocks UltraTech Cement Limited 1. Xtralite - AAC Blocks Zuari Cement Limited 1. Super lite- AACblocks
A7: 4 | B7: Waterproofing | C7: NA | D7: Pedilite /Roff
A8: 5 | B8: False Flooring | C8: NA | D8: United insulation /Flexi floor (aet) / Kebao / Innerspace
A9: 6 | B9: Bubble sheet | C9: NA | D9: Cello
A10: 7 | B10: SS Sink | C10: NA | D10: Nirali
A11: 8 | B11: Sanitarywares & Faucets
A12: 8.01 | B12: Pillar cock | C12: Water Flow Rate at 3 Bar pressure | D12: Jaguar Use Jaquar Make with model no. 021KNG with flow rate of 2.5 LPM @ pressure of 3 Bar. Pl note Suffix G in model no. is critical to get desired flow rate. Cera F2013101- FOUNTAIN - Pillar cock with aerator F1001101- PLATINUM - Pillar cock with aerator F1015101-VICTOR - Pillar cock with aerator Hindware : F730002CP : Contessa Neo Pillar Cock Long Neck F740001CP : Dove Pillar cock
A13: 8.02 | B13: Sink cock | C13: Water Flow Rate at 3 Bar pressure | D13: Jaguar Use Jaquar Make and same model with Suffix GD (like 349 KNGD) with flow rate of 3.8 LPM @ pressure of 3 Bar. Pl note Suffix GD in model no. is critical to get desired flow rate. Cera F1016251-CHELSEA - Sink cock (wall mounted) with 200 mm (8″) long swivel spout and wall flange F1002251 - CARBON - Sink cock (wall mounted) with 150 mm (6″) long swivel spout and aerator F2013251 - FOUNTAIN - Sink cock (wall mounted) with 150 mm (6″) long swivel spout and aerator Hindware F200024CP :Classik Sink Cock With Swivel Casted Spout (Wall Mounted) F120021CP :Axxis Sink Cock With Normal Swinging Spout (Wall Mounted)
A14: 8.03 | B14: Two way bib cock | C14: Water Flow Rate at 3 Bar pressure | D14: Jaguar Use Jaquar Make with model no. 043NG with flow rate of 2.5 LPM @ pressure of 3 Bar. Pl note Suffix G in model no. is critical to get desired flow rate. Cera F2013163-FOUNTAIN - 2-way Bib cock with single handle and wall flange F1003161- TITANUM - 2-Way bib cock with wall flange and aerator Hindware : F200004CP :Classik Bib Cock 2 In 1 F120003CP :Axxis Bib Cock 2 In 1
A15: 8.04 | B15: Angle cock | C15: NA | D15: Jaguar : CON-CHR-059KN Hindware : F200005CP :Classik Angular Stop Cock
A16: 8.05 | B16: Concealed stop cock | C16: NA | D16: Jaguar : CON-CHR-083FTK Hindware : F200007CP : Classik Concealed Stop Cock- 15 / 20 mm
A17: 8.06 | B17: Urinal - Flush Valve | C17: Water Flow Rate | D17: Jaguar Use Jaquar Make with model no. 077G with flow rate of 1.5 LPF. Pl note Suffix G in model no. is critical to get desired flow rate. Cera - F9020203 : Self closing angle cock pressmatic for urinal with wall flange and 200 mm connecting pipe
A18: 8.07 | B18: Tower rail (450 mm) | C18: NA | D18: ACN-1111BNM
A19: 8.08 | B19: Towel ring | C19: NA | D19: ACN-CHR-1121N
A20: 8.09 | B20: Soap dispenser | C20: NA | D20: ACN-CHR-1135N
A21: 8.1 | B21: Toilet roll holder | C21: NA | D21: ACN-CHR-1153S
A22: 8.11 | B22: Hook | C22: NA | D22: ANC-1161N
A23: 8.12 | B23: Jet spray | C23: Water Flow Rate at 3 Bar pressure | D23: Jaguar Use Jaquar Make with model no. 565GA with flow rate of 6 LPM @ pressure of 3 Bar. Pl note Suffix GA in model no. is critical to get desired flow rate. Cera F8030101 / F8030102 / F8030103 / F8030104AB /F8030105AB / F8030109AB - Health Faucet ABS body with 1 meter SS braided connection pipe
... A27: 8.16 | B27: SS Sink | C27: NA | D27: Nirali - Grace plain - Small (485mm x 410mm) glossy
A28: 8.17a | B28: Wall hung Water closet (Ceramic Fitting) | C28: Green Pro Certification | D28: Hindware - ATHENS One Piece Closet 92511/ Mario Extended Wall Mounted Closet 20084 / Element 92082 /Florence Coupled Closet 92058 / Constellation Extended Wall Mounted Closet 20028. Cera - CAMPBELL S1021109 S Trap 120 mm S1021110 P Trap/ CURTIS S1031111 P Trap /
A29: 8.17b | B29: Water Closet With Flush Valve | C29: Water Flow rate | D29: Jaguar Suggesting use of jaguar make with model number 1085G, 1085SQG, 1085DFPG, 1089G, 1089SQG, 1089DFPG (for flush valves) with flow rates of 4/2 LPF. Pl note Suffix G in model no is critical to get desired flow rate. Cera: F8010106 : Flush valve concealed push type (Double flow) 25 mm (1”) 4/2 LPF
A30: 8.17c | B30: Water Closet With Cistern | C30: Water Flow rate | D30: Cera S1021103 + S1060101 - Calibre deluxe ewc-S + Calibre cistern S1021104 + S1060104 -Callaghan two pc ewc-S + Callaghan cistern S1013110 - Campbell one pc ewc-S 110 mm S1021120 + B1020105 - Curtis two pc ewc-S S1021113 + S1060106 - Cruse two pc ewc-S S1041105 - Compact wall hung S1031111 + B1020105 - Curtis wall hung with Curtis PVC Cistern S1021132 + S1060122 - Cimberly two piece Water closet-S trap with Cimberly cistern Hindware Cleo - S-190/220 ESSENCE - 92051 ENIGMA SLIM 92502 ELEMENT 92081
A31: 8.19 | B31: Wall mounted / Table top Wash basin | C31: Green Pro Certification | D31: Hindware - Compac 10004 / Cleo 10012 WHITE CERA Wash basins - CHIME S2040139 / CAMMY : S2090127 / CORBA : S2020104
A32: 8.2 | B32: Urinal | C32: Green Pro Certification | D32: CERA Sanitaryware - URINAL Urinal Flat Back with integrated EFS 360 x 330 x 740 mm (S4010101) Hindware : 60020 : FB- Eureka Standard Urinal
A33: 8.21 | B33: Under counter wash basin | C33: NA | D33: Hindware Round 10065 / Zen 10049 WHITE / Cera
A34: 10 | B34: PVC/ CPVC/UPVC pipe | C34: NA | D34: Astral / Prince / Precision
A35: 11 | B35: Anti Termite | C35: NA | D35: PCI / Hicare
B37: Flooring
A38: 1 | B38: Tiles | C38: Green Pro Certification | D38: Somany : Ultra Charge -Vitro - Milky White (800 x 800) Ultra charge - Vitro - Berlineta White ( 800 x 800 ) Delmon Beige - (600 x 600) Prism Johnson JOHNSON MARBONITE - DOUBLE CHARGE JOHNSON REFLECTO Nitco Duracottura Tiles Wall Tiles
A39: 3 | B39: Vinyl Flooring | C39: NA | D39: Armstrong/Tusker
B41: Carpentry Items
A42: 1 | B42: BWR Plywood | C42: Green Pro Certification | D42: Vidya Ply and Board Pvt Ltd , Samrat,
A43: 1.1 | B43: Commercial Plywood Plywood with "Free of Urea Formaldehyde" | C43: Free of Urea Formaldehyde , FSC Certified, IGBC Registered | D43: Century,V-CAN,Green Ply
A44: 2 | B44: Marine Plywood Plywood with "Free of Urea Formaldehyde" | C44: Free of Urea Formaldehyde , FSC Certified, IGBC Registered | D44: Century, Samrat, V-CAN,Green Ply,
A45: 4 | B45: Partition Framework | C45: NA | D45: Aluminium sections / India Gypsum : GI METAL FRAME PARTITION SYSTEM
...
